[2021-07-12 17:52:31] log.ERROR: Symfony\Component\Debug\Exception\FatalErrorException: Class User contains 3 abstract methods and must therefore be declared abstract or implement the remaining methods (Illuminate\Auth\UserInterface::getRememberToken, Illuminate\Auth\UserInterface::setRememberToken, Illuminate\Auth\UserInterface::getRememberTokenName) in E:\xampp\htdocs\basic_auth_site\app\models\User.php:6 Stack trace: #0 [internal function]: Illuminate\Exception\Handler->handleShutdown() #1 {main} [] []
[2021-07-12 17:53:29] log.ERROR: Symfony\Component\Debug\Exception\FatalErrorException: Uncaught TypeError: Argument 1 passed to Illuminate\Exception\WhoopsDisplayer::display() must be an instance of Exception, instance of Error given, called in E:\xampp\htdocs\basic_auth_site\vendor\laravel\framework\src\Illuminate\Exception\Handler.php on line 275 and defined in E:\xampp\htdocs\basic_auth_site\vendor\laravel\framework\src\Illuminate\Exception\WhoopsDisplayer.php:40 Stack trace: #0 E:\xampp\htdocs\basic_auth_site\vendor\laravel\framework\src\Illuminate\Exception\Handler.php(275): Illuminate\Exception\WhoopsDisplayer->display(Object(Error)) #1 E:\xampp\htdocs\basic_auth_site\vendor\laravel\framework\src\Illuminate\Exception\Handler.php(162): Illuminate\Exception\Handler->displayException(Object(Error)) #2 [internal function]: Illuminate\Exception\Handler->handleException(Object(Error)) #3 {main}   thrown in E:\xampp\htdocs\basic_auth_site\vendor\laravel\framework\src\Illuminate\Exception\WhoopsDisplayer.php:40 Stack trace: #0 [internal function]: Illuminate\Exception\Handler->handleShutdown() #1 {main} [] []
[2021-07-12 17:54:11] log.ERROR: Symfony\Component\Debug\Exception\FatalErrorException: Class User contains 3 abstract methods and must therefore be declared abstract or implement the remaining methods (Illuminate\Auth\UserInterface::getRememberToken, Illuminate\Auth\UserInterface::setRememberToken, Illuminate\Auth\UserInterface::getRememberTokenName) in E:\xampp\htdocs\basic_auth_site\app\models\User.php:6 Stack trace: #0 [internal function]: Illuminate\Exception\Handler->handleShutdown() #1 {main} [] []
[2021-07-12 17:54:52] log.ERROR: Symfony\Component\Debug\Exception\FatalErrorException: Uncaught TypeError: Argument 1 passed to Illuminate\Exception\WhoopsDisplayer::display() must be an instance of Exception, instance of Error given, called in E:\xampp\htdocs\basic_auth_site\vendor\laravel\framework\src\Illuminate\Exception\Handler.php on line 275 and defined in E:\xampp\htdocs\basic_auth_site\vendor\laravel\framework\src\Illuminate\Exception\WhoopsDisplayer.php:40 Stack trace: #0 E:\xampp\htdocs\basic_auth_site\vendor\laravel\framework\src\Illuminate\Exception\Handler.php(275): Illuminate\Exception\WhoopsDisplayer->display(Object(Error)) #1 E:\xampp\htdocs\basic_auth_site\vendor\laravel\framework\src\Illuminate\Exception\Handler.php(162): Illuminate\Exception\Handler->displayException(Object(Error)) #2 [internal function]: Illuminate\Exception\Handler->handleException(Object(Error)) #3 {main}   thrown in E:\xampp\htdocs\basic_auth_site\vendor\laravel\framework\src\Illuminate\Exception\WhoopsDisplayer.php:40 Stack trace: #0 [internal function]: Illuminate\Exception\Handler->handleShutdown() #1 {main} [] []
[2021-07-12 18:06:24] log.ERROR: Symfony\Component\Debug\Exception\FatalErrorException: Class User contains 3 abstract methods and must therefore be declared abstract or implement the remaining methods (Illuminate\Auth\UserInterface::getRememberToken, Illuminate\Auth\UserInterface::setRememberToken, Illuminate\Auth\UserInterface::getRememberTokenName) in E:\xampp\htdocs\basic_auth_site\app\models\User.php:6 Stack trace: #0 [internal function]: Illuminate\Exception\Handler->handleShutdown() #1 {main} [] []
[2021-07-12 18:39:56] log.ERROR: Symfony\Component\Debug\Exception\FatalErrorException: Class User contains 3 abstract methods and must therefore be declared abstract or implement the remaining methods (Illuminate\Auth\UserInterface::getRememberToken, Illuminate\Auth\UserInterface::setRememberToken, Illuminate\Auth\UserInterface::getRememberTokenName) in E:\xampp\htdocs\basic_auth_site\app\models\User.php:6 Stack trace: #0 [internal function]: Illuminate\Exception\Handler->handleShutdown() #1 {main} [] []
[2021-07-12 18:40:01] log.ERROR: Symfony\Component\Debug\Exception\FatalErrorException: Class User contains 3 abstract methods and must therefore be declared abstract or implement the remaining methods (Illuminate\Auth\UserInterface::getRememberToken, Illuminate\Auth\UserInterface::setRememberToken, Illuminate\Auth\UserInterface::getRememberTokenName) in E:\xampp\htdocs\basic_auth_site\app\models\User.php:6 Stack trace: #0 [internal function]: Illuminate\Exception\Handler->handleShutdown() #1 {main} [] []
[2021-07-12 18:40:02] log.ERROR: Symfony\Component\Debug\Exception\FatalErrorException: Class User contains 3 abstract methods and must therefore be declared abstract or implement the remaining methods (Illuminate\Auth\UserInterface::getRememberToken, Illuminate\Auth\UserInterface::setRememberToken, Illuminate\Auth\UserInterface::getRememberTokenName) in E:\xampp\htdocs\basic_auth_site\app\models\User.php:6 Stack trace: #0 [internal function]: Illuminate\Exception\Handler->handleShutdown() #1 {main} [] []
[2021-07-12 18:40:03] log.ERROR: Symfony\Component\Debug\Exception\FatalErrorException: Class User contains 3 abstract methods and must therefore be declared abstract or implement the remaining methods (Illuminate\Auth\UserInterface::getRememberToken, Illuminate\Auth\UserInterface::setRememberToken, Illuminate\Auth\UserInterface::getRememberTokenName) in E:\xampp\htdocs\basic_auth_site\app\models\User.php:6 Stack trace: #0 [internal function]: Illuminate\Exception\Handler->handleShutdown() #1 {main} [] []
[2021-07-12 18:46:35] log.ERROR: Symfony\Component\Debug\Exception\FatalErrorException: Class User contains 3 abstract methods and must therefore be declared abstract or implement the remaining methods (Illuminate\Auth\UserInterface::getRememberToken, Illuminate\Auth\UserInterface::setRememberToken, Illuminate\Auth\UserInterface::getRememberTokenName) in E:\xampp\htdocs\basic_auth_site\app\models\User.php:6 Stack trace: #0 [internal function]: Illuminate\Exception\Handler->handleShutdown() #1 {main} [] []
[2021-07-12 19:03:10] log.ERROR: Symfony\Component\Debug\Exception\FatalErrorException: Uncaught TypeError: Argument 1 passed to Illuminate\Exception\WhoopsDisplayer::display() must be an instance of Exception, instance of ParseError given, called in E:\xampp\htdocs\basic_auth_site\vendor\laravel\framework\src\Illuminate\Exception\Handler.php on line 275 and defined in E:\xampp\htdocs\basic_auth_site\vendor\laravel\framework\src\Illuminate\Exception\WhoopsDisplayer.php:40 Stack trace: #0 E:\xampp\htdocs\basic_auth_site\vendor\laravel\framework\src\Illuminate\Exception\Handler.php(275): Illuminate\Exception\WhoopsDisplayer->display(Object(ParseError)) #1 E:\xampp\htdocs\basic_auth_site\vendor\laravel\framework\src\Illuminate\Exception\Handler.php(162): Illuminate\Exception\Handler->displayException(Object(ParseError)) #2 [internal function]: Illuminate\Exception\Handler->handleException(Object(ParseError)) #3 {main}   thrown in E:\xampp\htdocs\basic_auth_site\vendor\laravel\framework\src\Illuminate\Exception\WhoopsDisplayer.php:40 Stack trace: #0 [internal function]: Illuminate\Exception\Handler->handleShutdown() #1 {main} [] []
[2021-07-12 19:03:46] log.ERROR: Symfony\Component\Debug\Exception\FatalErrorException: Uncaught TypeError: Argument 1 passed to Illuminate\Exception\WhoopsDisplayer::display() must be an instance of Exception, instance of ParseError given, called in E:\xampp\htdocs\basic_auth_site\vendor\laravel\framework\src\Illuminate\Exception\Handler.php on line 275 and defined in E:\xampp\htdocs\basic_auth_site\vendor\laravel\framework\src\Illuminate\Exception\WhoopsDisplayer.php:40 Stack trace: #0 E:\xampp\htdocs\basic_auth_site\vendor\laravel\framework\src\Illuminate\Exception\Handler.php(275): Illuminate\Exception\WhoopsDisplayer->display(Object(ParseError)) #1 E:\xampp\htdocs\basic_auth_site\vendor\laravel\framework\src\Illuminate\Exception\Handler.php(162): Illuminate\Exception\Handler->displayException(Object(ParseError)) #2 [internal function]: Illuminate\Exception\Handler->handleException(Object(ParseError)) #3 {main}   thrown in E:\xampp\htdocs\basic_auth_site\vendor\laravel\framework\src\Illuminate\Exception\WhoopsDisplayer.php:40 Stack trace: #0 [internal function]: Illuminate\Exception\Handler->handleShutdown() #1 {main} [] []
[2021-07-12 19:04:27] log.ERROR: Symfony\Component\Debug\Exception\FatalErrorException: Uncaught TypeError: Argument 1 passed to Illuminate\Exception\WhoopsDisplayer::display() must be an instance of Exception, instance of ParseError given, called in E:\xampp\htdocs\basic_auth_site\vendor\laravel\framework\src\Illuminate\Exception\Handler.php on line 275 and defined in E:\xampp\htdocs\basic_auth_site\vendor\laravel\framework\src\Illuminate\Exception\WhoopsDisplayer.php:40 Stack trace: #0 E:\xampp\htdocs\basic_auth_site\vendor\laravel\framework\src\Illuminate\Exception\Handler.php(275): Illuminate\Exception\WhoopsDisplayer->display(Object(ParseError)) #1 E:\xampp\htdocs\basic_auth_site\vendor\laravel\framework\src\Illuminate\Exception\Handler.php(162): Illuminate\Exception\Handler->displayException(Object(ParseError)) #2 [internal function]: Illuminate\Exception\Handler->handleException(Object(ParseError)) #3 {main}   thrown in E:\xampp\htdocs\basic_auth_site\vendor\laravel\framework\src\Illuminate\Exception\WhoopsDisplayer.php:40 Stack trace: #0 [internal function]: Illuminate\Exception\Handler->handleShutdown() #1 {main} [] []
[2021-07-12 19:04:28] log.ERROR: Symfony\Component\Debug\Exception\FatalErrorException: Uncaught TypeError: Argument 1 passed to Illuminate\Exception\WhoopsDisplayer::display() must be an instance of Exception, instance of ParseError given, called in E:\xampp\htdocs\basic_auth_site\vendor\laravel\framework\src\Illuminate\Exception\Handler.php on line 275 and defined in E:\xampp\htdocs\basic_auth_site\vendor\laravel\framework\src\Illuminate\Exception\WhoopsDisplayer.php:40 Stack trace: #0 E:\xampp\htdocs\basic_auth_site\vendor\laravel\framework\src\Illuminate\Exception\Handler.php(275): Illuminate\Exception\WhoopsDisplayer->display(Object(ParseError)) #1 E:\xampp\htdocs\basic_auth_site\vendor\laravel\framework\src\Illuminate\Exception\Handler.php(162): Illuminate\Exception\Handler->displayException(Object(ParseError)) #2 [internal function]: Illuminate\Exception\Handler->handleException(Object(ParseError)) #3 {main}   thrown in E:\xampp\htdocs\basic_auth_site\vendor\laravel\framework\src\Illuminate\Exception\WhoopsDisplayer.php:40 Stack trace: #0 [internal function]: Illuminate\Exception\Handler->handleShutdown() #1 {main} [] []
[2021-07-12 19:04:28] log.ERROR: Symfony\Component\Debug\Exception\FatalErrorException: Uncaught TypeError: Argument 1 passed to Illuminate\Exception\WhoopsDisplayer::display() must be an instance of Exception, instance of ParseError given, called in E:\xampp\htdocs\basic_auth_site\vendor\laravel\framework\src\Illuminate\Exception\Handler.php on line 275 and defined in E:\xampp\htdocs\basic_auth_site\vendor\laravel\framework\src\Illuminate\Exception\WhoopsDisplayer.php:40 Stack trace: #0 E:\xampp\htdocs\basic_auth_site\vendor\laravel\framework\src\Illuminate\Exception\Handler.php(275): Illuminate\Exception\WhoopsDisplayer->display(Object(ParseError)) #1 E:\xampp\htdocs\basic_auth_site\vendor\laravel\framework\src\Illuminate\Exception\Handler.php(162): Illuminate\Exception\Handler->displayException(Object(ParseError)) #2 [internal function]: Illuminate\Exception\Handler->handleException(Object(ParseError)) #3 {main}   thrown in E:\xampp\htdocs\basic_auth_site\vendor\laravel\framework\src\Illuminate\Exception\WhoopsDisplayer.php:40 Stack trace: #0 [internal function]: Illuminate\Exception\Handler->handleShutdown() #1 {main} [] []
[2021-07-12 19:04:28] log.ERROR: Symfony\Component\Debug\Exception\FatalErrorException: Uncaught TypeError: Argument 1 passed to Illuminate\Exception\WhoopsDisplayer::display() must be an instance of Exception, instance of ParseError given, called in E:\xampp\htdocs\basic_auth_site\vendor\laravel\framework\src\Illuminate\Exception\Handler.php on line 275 and defined in E:\xampp\htdocs\basic_auth_site\vendor\laravel\framework\src\Illuminate\Exception\WhoopsDisplayer.php:40 Stack trace: #0 E:\xampp\htdocs\basic_auth_site\vendor\laravel\framework\src\Illuminate\Exception\Handler.php(275): Illuminate\Exception\WhoopsDisplayer->display(Object(ParseError)) #1 E:\xampp\htdocs\basic_auth_site\vendor\laravel\framework\src\Illuminate\Exception\Handler.php(162): Illuminate\Exception\Handler->displayException(Object(ParseError)) #2 [internal function]: Illuminate\Exception\Handler->handleException(Object(ParseError)) #3 {main}   thrown in E:\xampp\htdocs\basic_auth_site\vendor\laravel\framework\src\Illuminate\Exception\WhoopsDisplayer.php:40 Stack trace: #0 [internal function]: Illuminate\Exception\Handler->handleShutdown() #1 {main} [] []
[2021-07-12 19:04:28] log.ERROR: Symfony\Component\Debug\Exception\FatalErrorException: Uncaught TypeError: Argument 1 passed to Illuminate\Exception\WhoopsDisplayer::display() must be an instance of Exception, instance of ParseError given, called in E:\xampp\htdocs\basic_auth_site\vendor\laravel\framework\src\Illuminate\Exception\Handler.php on line 275 and defined in E:\xampp\htdocs\basic_auth_site\vendor\laravel\framework\src\Illuminate\Exception\WhoopsDisplayer.php:40 Stack trace: #0 E:\xampp\htdocs\basic_auth_site\vendor\laravel\framework\src\Illuminate\Exception\Handler.php(275): Illuminate\Exception\WhoopsDisplayer->display(Object(ParseError)) #1 E:\xampp\htdocs\basic_auth_site\vendor\laravel\framework\src\Illuminate\Exception\Handler.php(162): Illuminate\Exception\Handler->displayException(Object(ParseError)) #2 [internal function]: Illuminate\Exception\Handler->handleException(Object(ParseError)) #3 {main}   thrown in E:\xampp\htdocs\basic_auth_site\vendor\laravel\framework\src\Illuminate\Exception\WhoopsDisplayer.php:40 Stack trace: #0 [internal function]: Illuminate\Exception\Handler->handleShutdown() #1 {main} [] []
[2021-07-12 19:04:29] log.ERROR: Symfony\Component\Debug\Exception\FatalErrorException: Uncaught TypeError: Argument 1 passed to Illuminate\Exception\WhoopsDisplayer::display() must be an instance of Exception, instance of ParseError given, called in E:\xampp\htdocs\basic_auth_site\vendor\laravel\framework\src\Illuminate\Exception\Handler.php on line 275 and defined in E:\xampp\htdocs\basic_auth_site\vendor\laravel\framework\src\Illuminate\Exception\WhoopsDisplayer.php:40 Stack trace: #0 E:\xampp\htdocs\basic_auth_site\vendor\laravel\framework\src\Illuminate\Exception\Handler.php(275): Illuminate\Exception\WhoopsDisplayer->display(Object(ParseError)) #1 E:\xampp\htdocs\basic_auth_site\vendor\laravel\framework\src\Illuminate\Exception\Handler.php(162): Illuminate\Exception\Handler->displayException(Object(ParseError)) #2 [internal function]: Illuminate\Exception\Handler->handleException(Object(ParseError)) #3 {main}   thrown in E:\xampp\htdocs\basic_auth_site\vendor\laravel\framework\src\Illuminate\Exception\WhoopsDisplayer.php:40 Stack trace: #0 [internal function]: Illuminate\Exception\Handler->handleShutdown() #1 {main} [] []
[2021-07-12 19:04:29] log.ERROR: Symfony\Component\Debug\Exception\FatalErrorException: Uncaught TypeError: Argument 1 passed to Illuminate\Exception\WhoopsDisplayer::display() must be an instance of Exception, instance of ParseError given, called in E:\xampp\htdocs\basic_auth_site\vendor\laravel\framework\src\Illuminate\Exception\Handler.php on line 275 and defined in E:\xampp\htdocs\basic_auth_site\vendor\laravel\framework\src\Illuminate\Exception\WhoopsDisplayer.php:40 Stack trace: #0 E:\xampp\htdocs\basic_auth_site\vendor\laravel\framework\src\Illuminate\Exception\Handler.php(275): Illuminate\Exception\WhoopsDisplayer->display(Object(ParseError)) #1 E:\xampp\htdocs\basic_auth_site\vendor\laravel\framework\src\Illuminate\Exception\Handler.php(162): Illuminate\Exception\Handler->displayException(Object(ParseError)) #2 [internal function]: Illuminate\Exception\Handler->handleException(Object(ParseError)) #3 {main}   thrown in E:\xampp\htdocs\basic_auth_site\vendor\laravel\framework\src\Illuminate\Exception\WhoopsDisplayer.php:40 Stack trace: #0 [internal function]: Illuminate\Exception\Handler->handleShutdown() #1 {main} [] []
[2021-07-12 19:04:30] log.ERROR: Symfony\Component\Debug\Exception\FatalErrorException: Uncaught TypeError: Argument 1 passed to Illuminate\Exception\WhoopsDisplayer::display() must be an instance of Exception, instance of ParseError given, called in E:\xampp\htdocs\basic_auth_site\vendor\laravel\framework\src\Illuminate\Exception\Handler.php on line 275 and defined in E:\xampp\htdocs\basic_auth_site\vendor\laravel\framework\src\Illuminate\Exception\WhoopsDisplayer.php:40 Stack trace: #0 E:\xampp\htdocs\basic_auth_site\vendor\laravel\framework\src\Illuminate\Exception\Handler.php(275): Illuminate\Exception\WhoopsDisplayer->display(Object(ParseError)) #1 E:\xampp\htdocs\basic_auth_site\vendor\laravel\framework\src\Illuminate\Exception\Handler.php(162): Illuminate\Exception\Handler->displayException(Object(ParseError)) #2 [internal function]: Illuminate\Exception\Handler->handleException(Object(ParseError)) #3 {main}   thrown in E:\xampp\htdocs\basic_auth_site\vendor\laravel\framework\src\Illuminate\Exception\WhoopsDisplayer.php:40 Stack trace: #0 [internal function]: Illuminate\Exception\Handler->handleShutdown() #1 {main} [] []
[2021-07-12 19:04:30] log.ERROR: Symfony\Component\Debug\Exception\FatalErrorException: Uncaught TypeError: Argument 1 passed to Illuminate\Exception\WhoopsDisplayer::display() must be an instance of Exception, instance of ParseError given, called in E:\xampp\htdocs\basic_auth_site\vendor\laravel\framework\src\Illuminate\Exception\Handler.php on line 275 and defined in E:\xampp\htdocs\basic_auth_site\vendor\laravel\framework\src\Illuminate\Exception\WhoopsDisplayer.php:40 Stack trace: #0 E:\xampp\htdocs\basic_auth_site\vendor\laravel\framework\src\Illuminate\Exception\Handler.php(275): Illuminate\Exception\WhoopsDisplayer->display(Object(ParseError)) #1 E:\xampp\htdocs\basic_auth_site\vendor\laravel\framework\src\Illuminate\Exception\Handler.php(162): Illuminate\Exception\Handler->displayException(Object(ParseError)) #2 [internal function]: Illuminate\Exception\Handler->handleException(Object(ParseError)) #3 {main}   thrown in E:\xampp\htdocs\basic_auth_site\vendor\laravel\framework\src\Illuminate\Exception\WhoopsDisplayer.php:40 Stack trace: #0 [internal function]: Illuminate\Exception\Handler->handleShutdown() #1 {main} [] []
[2021-07-12 19:04:30] log.ERROR: Symfony\Component\Debug\Exception\FatalErrorException: Uncaught TypeError: Argument 1 passed to Illuminate\Exception\WhoopsDisplayer::display() must be an instance of Exception, instance of ParseError given, called in E:\xampp\htdocs\basic_auth_site\vendor\laravel\framework\src\Illuminate\Exception\Handler.php on line 275 and defined in E:\xampp\htdocs\basic_auth_site\vendor\laravel\framework\src\Illuminate\Exception\WhoopsDisplayer.php:40 Stack trace: #0 E:\xampp\htdocs\basic_auth_site\vendor\laravel\framework\src\Illuminate\Exception\Handler.php(275): Illuminate\Exception\WhoopsDisplayer->display(Object(ParseError)) #1 E:\xampp\htdocs\basic_auth_site\vendor\laravel\framework\src\Illuminate\Exception\Handler.php(162): Illuminate\Exception\Handler->displayException(Object(ParseError)) #2 [internal function]: Illuminate\Exception\Handler->handleException(Object(ParseError)) #3 {main}   thrown in E:\xampp\htdocs\basic_auth_site\vendor\laravel\framework\src\Illuminate\Exception\WhoopsDisplayer.php:40 Stack trace: #0 [internal function]: Illuminate\Exception\Handler->handleShutdown() #1 {main} [] []
[2021-07-12 19:04:31] log.ERROR: Symfony\Component\Debug\Exception\FatalErrorException: Uncaught TypeError: Argument 1 passed to Illuminate\Exception\WhoopsDisplayer::display() must be an instance of Exception, instance of ParseError given, called in E:\xampp\htdocs\basic_auth_site\vendor\laravel\framework\src\Illuminate\Exception\Handler.php on line 275 and defined in E:\xampp\htdocs\basic_auth_site\vendor\laravel\framework\src\Illuminate\Exception\WhoopsDisplayer.php:40 Stack trace: #0 E:\xampp\htdocs\basic_auth_site\vendor\laravel\framework\src\Illuminate\Exception\Handler.php(275): Illuminate\Exception\WhoopsDisplayer->display(Object(ParseError)) #1 E:\xampp\htdocs\basic_auth_site\vendor\laravel\framework\src\Illuminate\Exception\Handler.php(162): Illuminate\Exception\Handler->displayException(Object(ParseError)) #2 [internal function]: Illuminate\Exception\Handler->handleException(Object(ParseError)) #3 {main}   thrown in E:\xampp\htdocs\basic_auth_site\vendor\laravel\framework\src\Illuminate\Exception\WhoopsDisplayer.php:40 Stack trace: #0 [internal function]: Illuminate\Exception\Handler->handleShutdown() #1 {main} [] []
[2021-07-12 19:04:31] log.ERROR: Symfony\Component\Debug\Exception\FatalErrorException: Uncaught TypeError: Argument 1 passed to Illuminate\Exception\WhoopsDisplayer::display() must be an instance of Exception, instance of ParseError given, called in E:\xampp\htdocs\basic_auth_site\vendor\laravel\framework\src\Illuminate\Exception\Handler.php on line 275 and defined in E:\xampp\htdocs\basic_auth_site\vendor\laravel\framework\src\Illuminate\Exception\WhoopsDisplayer.php:40 Stack trace: #0 E:\xampp\htdocs\basic_auth_site\vendor\laravel\framework\src\Illuminate\Exception\Handler.php(275): Illuminate\Exception\WhoopsDisplayer->display(Object(ParseError)) #1 E:\xampp\htdocs\basic_auth_site\vendor\laravel\framework\src\Illuminate\Exception\Handler.php(162): Illuminate\Exception\Handler->displayException(Object(ParseError)) #2 [internal function]: Illuminate\Exception\Handler->handleException(Object(ParseError)) #3 {main}   thrown in E:\xampp\htdocs\basic_auth_site\vendor\laravel\framework\src\Illuminate\Exception\WhoopsDisplayer.php:40 Stack trace: #0 [internal function]: Illuminate\Exception\Handler->handleShutdown() #1 {main} [] []
[2021-07-12 19:04:31] log.ERROR: Symfony\Component\Debug\Exception\FatalErrorException: Uncaught TypeError: Argument 1 passed to Illuminate\Exception\WhoopsDisplayer::display() must be an instance of Exception, instance of ParseError given, called in E:\xampp\htdocs\basic_auth_site\vendor\laravel\framework\src\Illuminate\Exception\Handler.php on line 275 and defined in E:\xampp\htdocs\basic_auth_site\vendor\laravel\framework\src\Illuminate\Exception\WhoopsDisplayer.php:40 Stack trace: #0 E:\xampp\htdocs\basic_auth_site\vendor\laravel\framework\src\Illuminate\Exception\Handler.php(275): Illuminate\Exception\WhoopsDisplayer->display(Object(ParseError)) #1 E:\xampp\htdocs\basic_auth_site\vendor\laravel\framework\src\Illuminate\Exception\Handler.php(162): Illuminate\Exception\Handler->displayException(Object(ParseError)) #2 [internal function]: Illuminate\Exception\Handler->handleException(Object(ParseError)) #3 {main}   thrown in E:\xampp\htdocs\basic_auth_site\vendor\laravel\framework\src\Illuminate\Exception\WhoopsDisplayer.php:40 Stack trace: #0 [internal function]: Illuminate\Exception\Handler->handleShutdown() #1 {main} [] []
[2021-07-12 19:04:31] log.ERROR: Symfony\Component\Debug\Exception\FatalErrorException: Uncaught TypeError: Argument 1 passed to Illuminate\Exception\WhoopsDisplayer::display() must be an instance of Exception, instance of ParseError given, called in E:\xampp\htdocs\basic_auth_site\vendor\laravel\framework\src\Illuminate\Exception\Handler.php on line 275 and defined in E:\xampp\htdocs\basic_auth_site\vendor\laravel\framework\src\Illuminate\Exception\WhoopsDisplayer.php:40 Stack trace: #0 E:\xampp\htdocs\basic_auth_site\vendor\laravel\framework\src\Illuminate\Exception\Handler.php(275): Illuminate\Exception\WhoopsDisplayer->display(Object(ParseError)) #1 E:\xampp\htdocs\basic_auth_site\vendor\laravel\framework\src\Illuminate\Exception\Handler.php(162): Illuminate\Exception\Handler->displayException(Object(ParseError)) #2 [internal function]: Illuminate\Exception\Handler->handleException(Object(ParseError)) #3 {main}   thrown in E:\xampp\htdocs\basic_auth_site\vendor\laravel\framework\src\Illuminate\Exception\WhoopsDisplayer.php:40 Stack trace: #0 [internal function]: Illuminate\Exception\Handler->handleShutdown() #1 {main} [] []
[2021-07-12 19:04:57] log.ERROR: PDOException: SQLSTATE[42S02]: Base table or view not found: 1146 Table 'cam_words.users' doesn't exist in E:\xampp\htdocs\basic_auth_site\vendor\laravel\framework\src\Illuminate\Database\Connection.php:272 Stack trace: #0 E:\xampp\htdocs\basic_auth_site\vendor\laravel\framework\src\Illuminate\Database\Connection.php(272): PDO->prepare('select * from `...') #1 E:\xampp\htdocs\basic_auth_site\vendor\laravel\framework\src\Illuminate\Database\Connection.php(521): Illuminate\Database\Connection->Illuminate\Database\{closure}(Object(Illuminate\Database\MySqlConnection), 'select * from `...', Array) #2 E:\xampp\htdocs\basic_auth_site\vendor\laravel\framework\src\Illuminate\Database\Connection.php(277): Illuminate\Database\Connection->run('select * from `...', Array, Object(Closure)) #3 E:\xampp\htdocs\basic_auth_site\vendor\laravel\framework\src\Illuminate\Database\Query\Builder.php(1028): Illuminate\Database\Connection->select('select * from `...', Array) #4 E:\xampp\htdocs\basic_auth_site\vendor\laravel\framework\src\Illuminate\Database\Query\Builder.php(1018): Illuminate\Database\Query\Builder->runSelect() #5 E:\xampp\htdocs\basic_auth_site\vendor\laravel\framework\src\Illuminate\Database\Query\Builder.php(1005): Illuminate\Database\Query\Builder->getFresh(Array) #6 E:\xampp\htdocs\basic_auth_site\vendor\laravel\framework\src\Illuminate\Database\Query\Builder.php(990): Illuminate\Database\Query\Builder->get(Array) #7 E:\xampp\htdocs\basic_auth_site\vendor\laravel\framework\src\Illuminate\Auth\DatabaseUserProvider.php(118): Illuminate\Database\Query\Builder->first() #8 E:\xampp\htdocs\basic_auth_site\vendor\laravel\framework\src\Illuminate\Auth\Guard.php(300): Illuminate\Auth\DatabaseUserProvider->retrieveByCredentials(Array) #9 [internal function]: Illuminate\Auth\Guard->attempt(Array) #10 E:\xampp\htdocs\basic_auth_site\vendor\laravel\framework\src\Illuminate\Support\Manager.php(129): call_user_func_array(Array, Array) #11 E:\xampp\htdocs\basic_auth_site\vendor\laravel\framework\src\Illuminate\Support\Facades\Facade.php(206): Illuminate\Support\Manager->__call('attempt', Array) #12 E:\xampp\htdocs\basic_auth_site\app\controllers\HomeController.php(62): Illuminate\Support\Facades\Facade::__callStatic('attempt', Array) #13 [internal function]: HomeController->doLogin() #14 E:\xampp\htdocs\basic_auth_site\vendor\laravel\framework\src\Illuminate\Routing\Controllers\Controller.php(138): call_user_func_array(Array, Array) #15 E:\xampp\htdocs\basic_auth_site\vendor\laravel\framework\src\Illuminate\Routing\Controllers\Controller.php(115): Illuminate\Routing\Controllers\Controller->callMethod('doLogin', Array) #16 E:\xampp\htdocs\basic_auth_site\vendor\laravel\framework\src\Illuminate\Routing\Router.php(985): Illuminate\Routing\Controllers\Controller->callAction(Object(Illuminate\Foundation\Application), Object(Illuminate\Routing\Router), 'doLogin', Array) #17 [internal function]: Illuminate\Routing\Router->Illuminate\Routing\{closure}() #18 E:\xampp\htdocs\basic_auth_site\vendor\laravel\framework\src\Illuminate\Routing\Route.php(80): call_user_func_array(Object(Closure), Array) #19 E:\xampp\htdocs\basic_auth_site\vendor\laravel\framework\src\Illuminate\Routing\Route.php(47): Illuminate\Routing\Route->callCallable() #20 E:\xampp\htdocs\basic_auth_site\vendor\laravel\framework\src\Illuminate\Routing\Router.php(1016): Illuminate\Routing\Route->run(Object(Illuminate\Http\Request)) #21 E:\xampp\htdocs\basic_auth_site\vendor\laravel\framework\src\Illuminate\Foundation\Application.php(576): Illuminate\Routing\Router->dispatch(Object(Illuminate\Http\Request)) #22 E:\xampp\htdocs\basic_auth_site\vendor\laravel\framework\src\Illuminate\Foundation\Application.php(552): Illuminate\Foundation\Application->dispatch(Object(Illuminate\Http\Request)) #23 E:\xampp\htdocs\basic_auth_site\public\index.php(49): Illuminate\Foundation\Application->run() #24 {main}  Next Exception: SQLSTATE[42S02]: Base table or view not found: 1146 Table 'cam_words.users' doesn't exist (SQL: select * from `users` where `email` = ? limit 1) (Bindings: array (   0 => 'cameronall@gmail.com', )) in E:\xampp\htdocs\basic_auth_site\vendor\laravel\framework\src\Illuminate\Database\Connection.php:556 Stack trace: #0 E:\xampp\htdocs\basic_auth_site\vendor\laravel\framework\src\Illuminate\Database\Connection.php(529): Illuminate\Database\Connection->handleQueryException(Object(PDOException), 'select * from `...', 'array (\n  0 => ...') #1 E:\xampp\htdocs\basic_auth_site\vendor\laravel\framework\src\Illuminate\Database\Connection.php(277): Illuminate\Database\Connection->run('select * from `...', Array, Object(Closure)) #2 E:\xampp\htdocs\basic_auth_site\vendor\laravel\framework\src\Illuminate\Database\Query\Builder.php(1028): Illuminate\Database\Connection->select('select * from `...', Array) #3 E:\xampp\htdocs\basic_auth_site\vendor\laravel\framework\src\Illuminate\Database\Query\Builder.php(1018): Illuminate\Database\Query\Builder->runSelect() #4 E:\xampp\htdocs\basic_auth_site\vendor\laravel\framework\src\Illuminate\Database\Query\Builder.php(1005): Illuminate\Database\Query\Builder->getFresh(Array) #5 E:\xampp\htdocs\basic_auth_site\vendor\laravel\framework\src\Illuminate\Database\Query\Builder.php(990): Illuminate\Database\Query\Builder->get(Array) #6 E:\xampp\htdocs\basic_auth_site\vendor\laravel\framework\src\Illuminate\Auth\DatabaseUserProvider.php(118): Illuminate\Database\Query\Builder->first() #7 E:\xampp\htdocs\basic_auth_site\vendor\laravel\framework\src\Illuminate\Auth\Guard.php(300): Illuminate\Auth\DatabaseUserProvider->retrieveByCredentials(Array) #8 [internal function]: Illuminate\Auth\Guard->attempt(Array) #9 E:\xampp\htdocs\basic_auth_site\vendor\laravel\framework\src\Illuminate\Support\Manager.php(129): call_user_func_array(Array, Array) #10 E:\xampp\htdocs\basic_auth_site\vendor\laravel\framework\src\Illuminate\Support\Facades\Facade.php(206): Illuminate\Support\Manager->__call('attempt', Array) #11 E:\xampp\htdocs\basic_auth_site\app\controllers\HomeController.php(62): Illuminate\Support\Facades\Facade::__callStatic('attempt', Array) #12 [internal function]: HomeController->doLogin() #13 E:\xampp\htdocs\basic_auth_site\vendor\laravel\framework\src\Illuminate\Routing\Controllers\Controller.php(138): call_user_func_array(Array, Array) #14 E:\xampp\htdocs\basic_auth_site\vendor\laravel\framework\src\Illuminate\Routing\Controllers\Controller.php(115): Illuminate\Routing\Controllers\Controller->callMethod('doLogin', Array) #15 E:\xampp\htdocs\basic_auth_site\vendor\laravel\framework\src\Illuminate\Routing\Router.php(985): Illuminate\Routing\Controllers\Controller->callAction(Object(Illuminate\Foundation\Application), Object(Illuminate\Routing\Router), 'doLogin', Array) #16 [internal function]: Illuminate\Routing\Router->Illuminate\Routing\{closure}() #17 E:\xampp\htdocs\basic_auth_site\vendor\laravel\framework\src\Illuminate\Routing\Route.php(80): call_user_func_array(Object(Closure), Array) #18 E:\xampp\htdocs\basic_auth_site\vendor\laravel\framework\src\Illuminate\Routing\Route.php(47): Illuminate\Routing\Route->callCallable() #19 E:\xampp\htdocs\basic_auth_site\vendor\laravel\framework\src\Illuminate\Routing\Router.php(1016): Illuminate\Routing\Route->run(Object(Illuminate\Http\Request)) #20 E:\xampp\htdocs\basic_auth_site\vendor\laravel\framework\src\Illuminate\Foundation\Application.php(576): Illuminate\Routing\Router->dispatch(Object(Illuminate\Http\Request)) #21 E:\xampp\htdocs\basic_auth_site\vendor\laravel\framework\src\Illuminate\Foundation\Application.php(552): Illuminate\Foundation\Application->dispatch(Object(Illuminate\Http\Request)) #22 E:\xampp\htdocs\basic_auth_site\public\index.php(49): Illuminate\Foundation\Application->run() #23 {main} [] []
[2021-07-12 19:06:02] log.ERROR: ErrorException: Undefined variable: validator in E:\xampp\htdocs\basic_auth_site\app\controllers\HomeController.php:41 Stack trace: #0 E:\xampp\htdocs\basic_auth_site\app\controllers\HomeController.php(41): Illuminate\Exception\Handler->handleError(8, 'Undefined varia...', 'E:\\xampp\\htdocs...', 41, Array) #1 [internal function]: HomeController->doLogin() #2 E:\xampp\htdocs\basic_auth_site\vendor\laravel\framework\src\Illuminate\Routing\Controllers\Controller.php(138): call_user_func_array(Array, Array) #3 E:\xampp\htdocs\basic_auth_site\vendor\laravel\framework\src\Illuminate\Routing\Controllers\Controller.php(115): Illuminate\Routing\Controllers\Controller->callMethod('doLogin', Array) #4 E:\xampp\htdocs\basic_auth_site\vendor\laravel\framework\src\Illuminate\Routing\Router.php(985): Illuminate\Routing\Controllers\Controller->callAction(Object(Illuminate\Foundation\Application), Object(Illuminate\Routing\Router), 'doLogin', Array) #5 [internal function]: Illuminate\Routing\Router->Illuminate\Routing\{closure}() #6 E:\xampp\htdocs\basic_auth_site\vendor\laravel\framework\src\Illuminate\Routing\Route.php(80): call_user_func_array(Object(Closure), Array) #7 E:\xampp\htdocs\basic_auth_site\vendor\laravel\framework\src\Illuminate\Routing\Route.php(47): Illuminate\Routing\Route->callCallable() #8 E:\xampp\htdocs\basic_auth_site\vendor\laravel\framework\src\Illuminate\Routing\Router.php(1016): Illuminate\Routing\Route->run(Object(Illuminate\Http\Request)) #9 E:\xampp\htdocs\basic_auth_site\vendor\laravel\framework\src\Illuminate\Foundation\Application.php(576): Illuminate\Routing\Router->dispatch(Object(Illuminate\Http\Request)) #10 E:\xampp\htdocs\basic_auth_site\vendor\laravel\framework\src\Illuminate\Foundation\Application.php(552): Illuminate\Foundation\Application->dispatch(Object(Illuminate\Http\Request)) #11 E:\xampp\htdocs\basic_auth_site\public\index.php(49): Illuminate\Foundation\Application->run() #12 {main} [] []
[2021-07-12 19:06:04] log.ERROR: ErrorException: Undefined variable: validator in E:\xampp\htdocs\basic_auth_site\app\controllers\HomeController.php:41 Stack trace: #0 E:\xampp\htdocs\basic_auth_site\app\controllers\HomeController.php(41): Illuminate\Exception\Handler->handleError(8, 'Undefined varia...', 'E:\\xampp\\htdocs...', 41, Array) #1 [internal function]: HomeController->doLogin() #2 E:\xampp\htdocs\basic_auth_site\vendor\laravel\framework\src\Illuminate\Routing\Controllers\Controller.php(138): call_user_func_array(Array, Array) #3 E:\xampp\htdocs\basic_auth_site\vendor\laravel\framework\src\Illuminate\Routing\Controllers\Controller.php(115): Illuminate\Routing\Controllers\Controller->callMethod('doLogin', Array) #4 E:\xampp\htdocs\basic_auth_site\vendor\laravel\framework\src\Illuminate\Routing\Router.php(985): Illuminate\Routing\Controllers\Controller->callAction(Object(Illuminate\Foundation\Application), Object(Illuminate\Routing\Router), 'doLogin', Array) #5 [internal function]: Illuminate\Routing\Router->Illuminate\Routing\{closure}() #6 E:\xampp\htdocs\basic_auth_site\vendor\laravel\framework\src\Illuminate\Routing\Route.php(80): call_user_func_array(Object(Closure), Array) #7 E:\xampp\htdocs\basic_auth_site\vendor\laravel\framework\src\Illuminate\Routing\Route.php(47): Illuminate\Routing\Route->callCallable() #8 E:\xampp\htdocs\basic_auth_site\vendor\laravel\framework\src\Illuminate\Routing\Router.php(1016): Illuminate\Routing\Route->run(Object(Illuminate\Http\Request)) #9 E:\xampp\htdocs\basic_auth_site\vendor\laravel\framework\src\Illuminate\Foundation\Application.php(576): Illuminate\Routing\Router->dispatch(Object(Illuminate\Http\Request)) #10 E:\xampp\htdocs\basic_auth_site\vendor\laravel\framework\src\Illuminate\Foundation\Application.php(552): Illuminate\Foundation\Application->dispatch(Object(Illuminate\Http\Request)) #11 E:\xampp\htdocs\basic_auth_site\public\index.php(49): Illuminate\Foundation\Application->run() #12 {main} [] []
[2021-07-12 19:06:21] log.ERROR: Symfony\Component\Debug\Exception\FatalErrorException: Uncaught TypeError: Argument 1 passed to Illuminate\Exception\WhoopsDisplayer::display() must be an instance of Exception, instance of ParseError given, called in E:\xampp\htdocs\basic_auth_site\vendor\laravel\framework\src\Illuminate\Exception\Handler.php on line 275 and defined in E:\xampp\htdocs\basic_auth_site\vendor\laravel\framework\src\Illuminate\Exception\WhoopsDisplayer.php:40 Stack trace: #0 E:\xampp\htdocs\basic_auth_site\vendor\laravel\framework\src\Illuminate\Exception\Handler.php(275): Illuminate\Exception\WhoopsDisplayer->display(Object(ParseError)) #1 E:\xampp\htdocs\basic_auth_site\vendor\laravel\framework\src\Illuminate\Exception\Handler.php(162): Illuminate\Exception\Handler->displayException(Object(ParseError)) #2 [internal function]: Illuminate\Exception\Handler->handleException(Object(ParseError)) #3 {main}   thrown in E:\xampp\htdocs\basic_auth_site\vendor\laravel\framework\src\Illuminate\Exception\WhoopsDisplayer.php:40 Stack trace: #0 [internal function]: Illuminate\Exception\Handler->handleShutdown() #1 {main} [] []
[2021-07-12 19:06:47] log.ERROR: Symfony\Component\Debug\Exception\FatalErrorException: Uncaught TypeError: Argument 1 passed to Illuminate\Exception\WhoopsDisplayer::display() must be an instance of Exception, instance of ParseError given, called in E:\xampp\htdocs\basic_auth_site\vendor\laravel\framework\src\Illuminate\Exception\Handler.php on line 275 and defined in E:\xampp\htdocs\basic_auth_site\vendor\laravel\framework\src\Illuminate\Exception\WhoopsDisplayer.php:40 Stack trace: #0 E:\xampp\htdocs\basic_auth_site\vendor\laravel\framework\src\Illuminate\Exception\Handler.php(275): Illuminate\Exception\WhoopsDisplayer->display(Object(ParseError)) #1 E:\xampp\htdocs\basic_auth_site\vendor\laravel\framework\src\Illuminate\Exception\Handler.php(162): Illuminate\Exception\Handler->displayException(Object(ParseError)) #2 [internal function]: Illuminate\Exception\Handler->handleException(Object(ParseError)) #3 {main}   thrown in E:\xampp\htdocs\basic_auth_site\vendor\laravel\framework\src\Illuminate\Exception\WhoopsDisplayer.php:40 Stack trace: #0 [internal function]: Illuminate\Exception\Handler->handleShutdown() #1 {main} [] []
[2021-07-12 19:07:06] log.ERROR: Symfony\Component\Debug\Exception\FatalErrorException: Uncaught TypeError: Argument 1 passed to Illuminate\Exception\WhoopsDisplayer::display() must be an instance of Exception, instance of ParseError given, called in E:\xampp\htdocs\basic_auth_site\vendor\laravel\framework\src\Illuminate\Exception\Handler.php on line 275 and defined in E:\xampp\htdocs\basic_auth_site\vendor\laravel\framework\src\Illuminate\Exception\WhoopsDisplayer.php:40 Stack trace: #0 E:\xampp\htdocs\basic_auth_site\vendor\laravel\framework\src\Illuminate\Exception\Handler.php(275): Illuminate\Exception\WhoopsDisplayer->display(Object(ParseError)) #1 E:\xampp\htdocs\basic_auth_site\vendor\laravel\framework\src\Illuminate\Exception\Handler.php(162): Illuminate\Exception\Handler->displayException(Object(ParseError)) #2 [internal function]: Illuminate\Exception\Handler->handleException(Object(ParseError)) #3 {main}   thrown in E:\xampp\htdocs\basic_auth_site\vendor\laravel\framework\src\Illuminate\Exception\WhoopsDisplayer.php:40 Stack trace: #0 [internal function]: Illuminate\Exception\Handler->handleShutdown() #1 {main} [] []
[2021-07-12 19:07:07] log.ERROR: Symfony\Component\Debug\Exception\FatalErrorException: Uncaught TypeError: Argument 1 passed to Illuminate\Exception\WhoopsDisplayer::display() must be an instance of Exception, instance of ParseError given, called in E:\xampp\htdocs\basic_auth_site\vendor\laravel\framework\src\Illuminate\Exception\Handler.php on line 275 and defined in E:\xampp\htdocs\basic_auth_site\vendor\laravel\framework\src\Illuminate\Exception\WhoopsDisplayer.php:40 Stack trace: #0 E:\xampp\htdocs\basic_auth_site\vendor\laravel\framework\src\Illuminate\Exception\Handler.php(275): Illuminate\Exception\WhoopsDisplayer->display(Object(ParseError)) #1 E:\xampp\htdocs\basic_auth_site\vendor\laravel\framework\src\Illuminate\Exception\Handler.php(162): Illuminate\Exception\Handler->displayException(Object(ParseError)) #2 [internal function]: Illuminate\Exception\Handler->handleException(Object(ParseError)) #3 {main}   thrown in E:\xampp\htdocs\basic_auth_site\vendor\laravel\framework\src\Illuminate\Exception\WhoopsDisplayer.php:40 Stack trace: #0 [internal function]: Illuminate\Exception\Handler->handleShutdown() #1 {main} [] []
[2021-07-12 19:07:07] log.ERROR: Symfony\Component\Debug\Exception\FatalErrorException: Uncaught TypeError: Argument 1 passed to Illuminate\Exception\WhoopsDisplayer::display() must be an instance of Exception, instance of ParseError given, called in E:\xampp\htdocs\basic_auth_site\vendor\laravel\framework\src\Illuminate\Exception\Handler.php on line 275 and defined in E:\xampp\htdocs\basic_auth_site\vendor\laravel\framework\src\Illuminate\Exception\WhoopsDisplayer.php:40 Stack trace: #0 E:\xampp\htdocs\basic_auth_site\vendor\laravel\framework\src\Illuminate\Exception\Handler.php(275): Illuminate\Exception\WhoopsDisplayer->display(Object(ParseError)) #1 E:\xampp\htdocs\basic_auth_site\vendor\laravel\framework\src\Illuminate\Exception\Handler.php(162): Illuminate\Exception\Handler->displayException(Object(ParseError)) #2 [internal function]: Illuminate\Exception\Handler->handleException(Object(ParseError)) #3 {main}   thrown in E:\xampp\htdocs\basic_auth_site\vendor\laravel\framework\src\Illuminate\Exception\WhoopsDisplayer.php:40 Stack trace: #0 [internal function]: Illuminate\Exception\Handler->handleShutdown() #1 {main} [] []
[2021-07-12 19:07:07] log.ERROR: Symfony\Component\Debug\Exception\FatalErrorException: Uncaught TypeError: Argument 1 passed to Illuminate\Exception\WhoopsDisplayer::display() must be an instance of Exception, instance of ParseError given, called in E:\xampp\htdocs\basic_auth_site\vendor\laravel\framework\src\Illuminate\Exception\Handler.php on line 275 and defined in E:\xampp\htdocs\basic_auth_site\vendor\laravel\framework\src\Illuminate\Exception\WhoopsDisplayer.php:40 Stack trace: #0 E:\xampp\htdocs\basic_auth_site\vendor\laravel\framework\src\Illuminate\Exception\Handler.php(275): Illuminate\Exception\WhoopsDisplayer->display(Object(ParseError)) #1 E:\xampp\htdocs\basic_auth_site\vendor\laravel\framework\src\Illuminate\Exception\Handler.php(162): Illuminate\Exception\Handler->displayException(Object(ParseError)) #2 [internal function]: Illuminate\Exception\Handler->handleException(Object(ParseError)) #3 {main}   thrown in E:\xampp\htdocs\basic_auth_site\vendor\laravel\framework\src\Illuminate\Exception\WhoopsDisplayer.php:40 Stack trace: #0 [internal function]: Illuminate\Exception\Handler->handleShutdown() #1 {main} [] []
[2021-07-12 19:39:14] log.ERROR: Symfony\Component\Debug\Exception\FatalErrorException: Uncaught TypeError: Argument 1 passed to Illuminate\Exception\WhoopsDisplayer::display() must be an instance of Exception, instance of Error given, called in E:\xampp\htdocs\basic_auth_site\vendor\laravel\framework\src\Illuminate\Exception\Handler.php on line 275 and defined in E:\xampp\htdocs\basic_auth_site\vendor\laravel\framework\src\Illuminate\Exception\WhoopsDisplayer.php:40 Stack trace: #0 E:\xampp\htdocs\basic_auth_site\vendor\laravel\framework\src\Illuminate\Exception\Handler.php(275): Illuminate\Exception\WhoopsDisplayer->display(Object(Error)) #1 E:\xampp\htdocs\basic_auth_site\vendor\laravel\framework\src\Illuminate\Exception\Handler.php(162): Illuminate\Exception\Handler->displayException(Object(Error)) #2 [internal function]: Illuminate\Exception\Handler->handleException(Object(Error)) #3 {main}   thrown in E:\xampp\htdocs\basic_auth_site\vendor\laravel\framework\src\Illuminate\Exception\WhoopsDisplayer.php:40 Stack trace: #0 [internal function]: Illuminate\Exception\Handler->handleShutdown() #1 {main} [] []
[2021-07-12 19:41:21] log.ERROR: Symfony\Component\Debug\Exception\FatalErrorException: Uncaught TypeError: Argument 1 passed to Illuminate\Exception\WhoopsDisplayer::display() must be an instance of Exception, instance of ParseError given, called in E:\xampp\htdocs\basic_auth_site\vendor\laravel\framework\src\Illuminate\Exception\Handler.php on line 275 and defined in E:\xampp\htdocs\basic_auth_site\vendor\laravel\framework\src\Illuminate\Exception\WhoopsDisplayer.php:40 Stack trace: #0 E:\xampp\htdocs\basic_auth_site\vendor\laravel\framework\src\Illuminate\Exception\Handler.php(275): Illuminate\Exception\WhoopsDisplayer->display(Object(ParseError)) #1 E:\xampp\htdocs\basic_auth_site\vendor\laravel\framework\src\Illuminate\Exception\Handler.php(162): Illuminate\Exception\Handler->displayException(Object(ParseError)) #2 [internal function]: Illuminate\Exception\Handler->handleException(Object(ParseError)) #3 {main}   thrown in E:\xampp\htdocs\basic_auth_site\vendor\laravel\framework\src\Illuminate\Exception\WhoopsDisplayer.php:40 Stack trace: #0 [internal function]: Illuminate\Exception\Handler->handleShutdown() #1 {main} [] []
[2021-07-12 19:42:29] log.ERROR: Symfony\Component\HttpKernel\Exception\MethodNotAllowedHttpException in E:\xampp\htdocs\basic_auth_site\vendor\laravel\framework\src\Illuminate\Routing\Router.php:1439 Stack trace: #0 E:\xampp\htdocs\basic_auth_site\vendor\laravel\framework\src\Illuminate\Routing\Router.php(1050): Illuminate\Routing\Router->handleRoutingException(Object(Symfony\Component\Routing\Exception\MethodNotAllowedException)) #1 E:\xampp\htdocs\basic_auth_site\vendor\laravel\framework\src\Illuminate\Routing\Router.php(1014): Illuminate\Routing\Router->findRoute(Object(Illuminate\Http\Request)) #2 E:\xampp\htdocs\basic_auth_site\vendor\laravel\framework\src\Illuminate\Foundation\Application.php(576): Illuminate\Routing\Router->dispatch(Object(Illuminate\Http\Request)) #3 E:\xampp\htdocs\basic_auth_site\vendor\laravel\framework\src\Illuminate\Foundation\Application.php(552): Illuminate\Foundation\Application->dispatch(Object(Illuminate\Http\Request)) #4 E:\xampp\htdocs\basic_auth_site\public\index.php(49): Illuminate\Foundation\Application->run() #5 {main} [] []
[2021-07-12 19:42:59] log.ERROR: Symfony\Component\HttpKernel\Exception\MethodNotAllowedHttpException in E:\xampp\htdocs\basic_auth_site\vendor\laravel\framework\src\Illuminate\Routing\Router.php:1439 Stack trace: #0 E:\xampp\htdocs\basic_auth_site\vendor\laravel\framework\src\Illuminate\Routing\Router.php(1050): Illuminate\Routing\Router->handleRoutingException(Object(Symfony\Component\Routing\Exception\MethodNotAllowedException)) #1 E:\xampp\htdocs\basic_auth_site\vendor\laravel\framework\src\Illuminate\Routing\Router.php(1014): Illuminate\Routing\Router->findRoute(Object(Illuminate\Http\Request)) #2 E:\xampp\htdocs\basic_auth_site\vendor\laravel\framework\src\Illuminate\Foundation\Application.php(576): Illuminate\Routing\Router->dispatch(Object(Illuminate\Http\Request)) #3 E:\xampp\htdocs\basic_auth_site\vendor\laravel\framework\src\Illuminate\Foundation\Application.php(552): Illuminate\Foundation\Application->dispatch(Object(Illuminate\Http\Request)) #4 E:\xampp\htdocs\basic_auth_site\public\index.php(49): Illuminate\Foundation\Application->run() #5 {main} [] []
[2021-07-12 19:43:47] log.ERROR: Symfony\Component\HttpKernel\Exception\MethodNotAllowedHttpException in E:\xampp\htdocs\basic_auth_site\vendor\laravel\framework\src\Illuminate\Routing\Router.php:1439 Stack trace: #0 E:\xampp\htdocs\basic_auth_site\vendor\laravel\framework\src\Illuminate\Routing\Router.php(1050): Illuminate\Routing\Router->handleRoutingException(Object(Symfony\Component\Routing\Exception\MethodNotAllowedException)) #1 E:\xampp\htdocs\basic_auth_site\vendor\laravel\framework\src\Illuminate\Routing\Router.php(1014): Illuminate\Routing\Router->findRoute(Object(Illuminate\Http\Request)) #2 E:\xampp\htdocs\basic_auth_site\vendor\laravel\framework\src\Illuminate\Foundation\Application.php(576): Illuminate\Routing\Router->dispatch(Object(Illuminate\Http\Request)) #3 E:\xampp\htdocs\basic_auth_site\vendor\laravel\framework\src\Illuminate\Foundation\Application.php(552): Illuminate\Foundation\Application->dispatch(Object(Illuminate\Http\Request)) #4 E:\xampp\htdocs\basic_auth_site\public\index.php(49): Illuminate\Foundation\Application->run() #5 {main} [] []
[2021-07-12 19:43:56] log.ERROR: Symfony\Component\HttpKernel\Exception\MethodNotAllowedHttpException in E:\xampp\htdocs\basic_auth_site\vendor\laravel\framework\src\Illuminate\Routing\Router.php:1439 Stack trace: #0 E:\xampp\htdocs\basic_auth_site\vendor\laravel\framework\src\Illuminate\Routing\Router.php(1050): Illuminate\Routing\Router->handleRoutingException(Object(Symfony\Component\Routing\Exception\MethodNotAllowedException)) #1 E:\xampp\htdocs\basic_auth_site\vendor\laravel\framework\src\Illuminate\Routing\Router.php(1014): Illuminate\Routing\Router->findRoute(Object(Illuminate\Http\Request)) #2 E:\xampp\htdocs\basic_auth_site\vendor\laravel\framework\src\Illuminate\Foundation\Application.php(576): Illuminate\Routing\Router->dispatch(Object(Illuminate\Http\Request)) #3 E:\xampp\htdocs\basic_auth_site\vendor\laravel\framework\src\Illuminate\Foundation\Application.php(552): Illuminate\Foundation\Application->dispatch(Object(Illuminate\Http\Request)) #4 E:\xampp\htdocs\basic_auth_site\public\index.php(49): Illuminate\Foundation\Application->run() #5 {main} [] []
[2021-07-12 19:44:03] log.ERROR: Symfony\Component\HttpKernel\Exception\MethodNotAllowedHttpException in E:\xampp\htdocs\basic_auth_site\vendor\laravel\framework\src\Illuminate\Routing\Router.php:1439 Stack trace: #0 E:\xampp\htdocs\basic_auth_site\vendor\laravel\framework\src\Illuminate\Routing\Router.php(1050): Illuminate\Routing\Router->handleRoutingException(Object(Symfony\Component\Routing\Exception\MethodNotAllowedException)) #1 E:\xampp\htdocs\basic_auth_site\vendor\laravel\framework\src\Illuminate\Routing\Router.php(1014): Illuminate\Routing\Router->findRoute(Object(Illuminate\Http\Request)) #2 E:\xampp\htdocs\basic_auth_site\vendor\laravel\framework\src\Illuminate\Foundation\Application.php(576): Illuminate\Routing\Router->dispatch(Object(Illuminate\Http\Request)) #3 E:\xampp\htdocs\basic_auth_site\vendor\laravel\framework\src\Illuminate\Foundation\Application.php(552): Illuminate\Foundation\Application->dispatch(Object(Illuminate\Http\Request)) #4 E:\xampp\htdocs\basic_auth_site\public\index.php(49): Illuminate\Foundation\Application->run() #5 {main} [] []
[2021-07-12 19:44:07] log.ERROR: Symfony\Component\HttpKernel\Exception\MethodNotAllowedHttpException in E:\xampp\htdocs\basic_auth_site\vendor\laravel\framework\src\Illuminate\Routing\Router.php:1439 Stack trace: #0 E:\xampp\htdocs\basic_auth_site\vendor\laravel\framework\src\Illuminate\Routing\Router.php(1050): Illuminate\Routing\Router->handleRoutingException(Object(Symfony\Component\Routing\Exception\MethodNotAllowedException)) #1 E:\xampp\htdocs\basic_auth_site\vendor\laravel\framework\src\Illuminate\Routing\Router.php(1014): Illuminate\Routing\Router->findRoute(Object(Illuminate\Http\Request)) #2 E:\xampp\htdocs\basic_auth_site\vendor\laravel\framework\src\Illuminate\Foundation\Application.php(576): Illuminate\Routing\Router->dispatch(Object(Illuminate\Http\Request)) #3 E:\xampp\htdocs\basic_auth_site\vendor\laravel\framework\src\Illuminate\Foundation\Application.php(552): Illuminate\Foundation\Application->dispatch(Object(Illuminate\Http\Request)) #4 E:\xampp\htdocs\basic_auth_site\public\index.php(49): Illuminate\Foundation\Application->run() #5 {main} [] []
[2021-07-12 19:44:16] log.ERROR: Symfony\Component\HttpKernel\Exception\MethodNotAllowedHttpException in E:\xampp\htdocs\basic_auth_site\vendor\laravel\framework\src\Illuminate\Routing\Router.php:1439 Stack trace: #0 E:\xampp\htdocs\basic_auth_site\vendor\laravel\framework\src\Illuminate\Routing\Router.php(1050): Illuminate\Routing\Router->handleRoutingException(Object(Symfony\Component\Routing\Exception\MethodNotAllowedException)) #1 E:\xampp\htdocs\basic_auth_site\vendor\laravel\framework\src\Illuminate\Routing\Router.php(1014): Illuminate\Routing\Router->findRoute(Object(Illuminate\Http\Request)) #2 E:\xampp\htdocs\basic_auth_site\vendor\laravel\framework\src\Illuminate\Foundation\Application.php(576): Illuminate\Routing\Router->dispatch(Object(Illuminate\Http\Request)) #3 E:\xampp\htdocs\basic_auth_site\vendor\laravel\framework\src\Illuminate\Foundation\Application.php(552): Illuminate\Foundation\Application->dispatch(Object(Illuminate\Http\Request)) #4 E:\xampp\htdocs\basic_auth_site\public\index.php(49): Illuminate\Foundation\Application->run() #5 {main} [] []
[2021-07-12 19:44:20] log.ERROR: Symfony\Component\HttpKernel\Exception\MethodNotAllowedHttpException in E:\xampp\htdocs\basic_auth_site\vendor\laravel\framework\src\Illuminate\Routing\Router.php:1439 Stack trace: #0 E:\xampp\htdocs\basic_auth_site\vendor\laravel\framework\src\Illuminate\Routing\Router.php(1050): Illuminate\Routing\Router->handleRoutingException(Object(Symfony\Component\Routing\Exception\MethodNotAllowedException)) #1 E:\xampp\htdocs\basic_auth_site\vendor\laravel\framework\src\Illuminate\Routing\Router.php(1014): Illuminate\Routing\Router->findRoute(Object(Illuminate\Http\Request)) #2 E:\xampp\htdocs\basic_auth_site\vendor\laravel\framework\src\Illuminate\Foundation\Application.php(576): Illuminate\Routing\Router->dispatch(Object(Illuminate\Http\Request)) #3 E:\xampp\htdocs\basic_auth_site\vendor\laravel\framework\src\Illuminate\Foundation\Application.php(552): Illuminate\Foundation\Application->dispatch(Object(Illuminate\Http\Request)) #4 E:\xampp\htdocs\basic_auth_site\public\index.php(49): Illuminate\Foundation\Application->run() #5 {main} [] []
[2021-07-12 19:44:51] log.ERROR: Symfony\Component\HttpKernel\Exception\MethodNotAllowedHttpException in E:\xampp\htdocs\basic_auth_site\vendor\laravel\framework\src\Illuminate\Routing\Router.php:1439 Stack trace: #0 E:\xampp\htdocs\basic_auth_site\vendor\laravel\framework\src\Illuminate\Routing\Router.php(1050): Illuminate\Routing\Router->handleRoutingException(Object(Symfony\Component\Routing\Exception\MethodNotAllowedException)) #1 E:\xampp\htdocs\basic_auth_site\vendor\laravel\framework\src\Illuminate\Routing\Router.php(1014): Illuminate\Routing\Router->findRoute(Object(Illuminate\Http\Request)) #2 E:\xampp\htdocs\basic_auth_site\vendor\laravel\framework\src\Illuminate\Foundation\Application.php(576): Illuminate\Routing\Router->dispatch(Object(Illuminate\Http\Request)) #3 E:\xampp\htdocs\basic_auth_site\vendor\laravel\framework\src\Illuminate\Foundation\Application.php(552): Illuminate\Foundation\Application->dispatch(Object(Illuminate\Http\Request)) #4 E:\xampp\htdocs\basic_auth_site\public\index.php(49): Illuminate\Foundation\Application->run() #5 {main} [] []
[2021-07-12 19:45:59] log.ERROR: Symfony\Component\HttpKernel\Exception\MethodNotAllowedHttpException in E:\xampp\htdocs\basic_auth_site\vendor\laravel\framework\src\Illuminate\Routing\Router.php:1439 Stack trace: #0 E:\xampp\htdocs\basic_auth_site\vendor\laravel\framework\src\Illuminate\Routing\Router.php(1050): Illuminate\Routing\Router->handleRoutingException(Object(Symfony\Component\Routing\Exception\MethodNotAllowedException)) #1 E:\xampp\htdocs\basic_auth_site\vendor\laravel\framework\src\Illuminate\Routing\Router.php(1014): Illuminate\Routing\Router->findRoute(Object(Illuminate\Http\Request)) #2 E:\xampp\htdocs\basic_auth_site\vendor\laravel\framework\src\Illuminate\Foundation\Application.php(576): Illuminate\Routing\Router->dispatch(Object(Illuminate\Http\Request)) #3 E:\xampp\htdocs\basic_auth_site\vendor\laravel\framework\src\Illuminate\Foundation\Application.php(552): Illuminate\Foundation\Application->dispatch(Object(Illuminate\Http\Request)) #4 E:\xampp\htdocs\basic_auth_site\public\index.php(49): Illuminate\Foundation\Application->run() #5 {main} [] []
[2021-07-12 19:46:06] log.ERROR: Symfony\Component\HttpKernel\Exception\MethodNotAllowedHttpException in E:\xampp\htdocs\basic_auth_site\vendor\laravel\framework\src\Illuminate\Routing\Router.php:1439 Stack trace: #0 E:\xampp\htdocs\basic_auth_site\vendor\laravel\framework\src\Illuminate\Routing\Router.php(1050): Illuminate\Routing\Router->handleRoutingException(Object(Symfony\Component\Routing\Exception\MethodNotAllowedException)) #1 E:\xampp\htdocs\basic_auth_site\vendor\laravel\framework\src\Illuminate\Routing\Router.php(1014): Illuminate\Routing\Router->findRoute(Object(Illuminate\Http\Request)) #2 E:\xampp\htdocs\basic_auth_site\vendor\laravel\framework\src\Illuminate\Foundation\Application.php(576): Illuminate\Routing\Router->dispatch(Object(Illuminate\Http\Request)) #3 E:\xampp\htdocs\basic_auth_site\vendor\laravel\framework\src\Illuminate\Foundation\Application.php(552): Illuminate\Foundation\Application->dispatch(Object(Illuminate\Http\Request)) #4 E:\xampp\htdocs\basic_auth_site\public\index.php(49): Illuminate\Foundation\Application->run() #5 {main} [] []
[2021-07-12 19:46:49] log.ERROR: Symfony\Component\HttpKernel\Exception\MethodNotAllowedHttpException in E:\xampp\htdocs\basic_auth_site\vendor\laravel\framework\src\Illuminate\Routing\Router.php:1439 Stack trace: #0 E:\xampp\htdocs\basic_auth_site\vendor\laravel\framework\src\Illuminate\Routing\Router.php(1050): Illuminate\Routing\Router->handleRoutingException(Object(Symfony\Component\Routing\Exception\MethodNotAllowedException)) #1 E:\xampp\htdocs\basic_auth_site\vendor\laravel\framework\src\Illuminate\Routing\Router.php(1014): Illuminate\Routing\Router->findRoute(Object(Illuminate\Http\Request)) #2 E:\xampp\htdocs\basic_auth_site\vendor\laravel\framework\src\Illuminate\Foundation\Application.php(576): Illuminate\Routing\Router->dispatch(Object(Illuminate\Http\Request)) #3 E:\xampp\htdocs\basic_auth_site\vendor\laravel\framework\src\Illuminate\Foundation\Application.php(552): Illuminate\Foundation\Application->dispatch(Object(Illuminate\Http\Request)) #4 E:\xampp\htdocs\basic_auth_site\public\index.php(49): Illuminate\Foundation\Application->run() #5 {main} [] []
[2021-07-12 19:46:59] log.ERROR: Symfony\Component\HttpKernel\Exception\MethodNotAllowedHttpException in E:\xampp\htdocs\basic_auth_site\vendor\laravel\framework\src\Illuminate\Routing\Router.php:1439 Stack trace: #0 E:\xampp\htdocs\basic_auth_site\vendor\laravel\framework\src\Illuminate\Routing\Router.php(1050): Illuminate\Routing\Router->handleRoutingException(Object(Symfony\Component\Routing\Exception\MethodNotAllowedException)) #1 E:\xampp\htdocs\basic_auth_site\vendor\laravel\framework\src\Illuminate\Routing\Router.php(1014): Illuminate\Routing\Router->findRoute(Object(Illuminate\Http\Request)) #2 E:\xampp\htdocs\basic_auth_site\vendor\laravel\framework\src\Illuminate\Foundation\Application.php(576): Illuminate\Routing\Router->dispatch(Object(Illuminate\Http\Request)) #3 E:\xampp\htdocs\basic_auth_site\vendor\laravel\framework\src\Illuminate\Foundation\Application.php(552): Illuminate\Foundation\Application->dispatch(Object(Illuminate\Http\Request)) #4 E:\xampp\htdocs\basic_auth_site\public\index.php(49): Illuminate\Foundation\Application->run() #5 {main} [] []
[2021-07-12 19:48:22] log.ERROR: Symfony\Component\HttpKernel\Exception\MethodNotAllowedHttpException in E:\xampp\htdocs\basic_auth_site\vendor\laravel\framework\src\Illuminate\Routing\Router.php:1439 Stack trace: #0 E:\xampp\htdocs\basic_auth_site\vendor\laravel\framework\src\Illuminate\Routing\Router.php(1050): Illuminate\Routing\Router->handleRoutingException(Object(Symfony\Component\Routing\Exception\MethodNotAllowedException)) #1 E:\xampp\htdocs\basic_auth_site\vendor\laravel\framework\src\Illuminate\Routing\Router.php(1014): Illuminate\Routing\Router->findRoute(Object(Illuminate\Http\Request)) #2 E:\xampp\htdocs\basic_auth_site\vendor\laravel\framework\src\Illuminate\Foundation\Application.php(576): Illuminate\Routing\Router->dispatch(Object(Illuminate\Http\Request)) #3 E:\xampp\htdocs\basic_auth_site\vendor\laravel\framework\src\Illuminate\Foundation\Application.php(552): Illuminate\Foundation\Application->dispatch(Object(Illuminate\Http\Request)) #4 E:\xampp\htdocs\basic_auth_site\public\index.php(49): Illuminate\Foundation\Application->run() #5 {main} [] []
[2021-07-12 19:48:58] log.ERROR: Symfony\Component\HttpKernel\Exception\MethodNotAllowedHttpException in E:\xampp\htdocs\basic_auth_site\vendor\laravel\framework\src\Illuminate\Routing\Router.php:1439 Stack trace: #0 E:\xampp\htdocs\basic_auth_site\vendor\laravel\framework\src\Illuminate\Routing\Router.php(1050): Illuminate\Routing\Router->handleRoutingException(Object(Symfony\Component\Routing\Exception\MethodNotAllowedException)) #1 E:\xampp\htdocs\basic_auth_site\vendor\laravel\framework\src\Illuminate\Routing\Router.php(1014): Illuminate\Routing\Router->findRoute(Object(Illuminate\Http\Request)) #2 E:\xampp\htdocs\basic_auth_site\vendor\laravel\framework\src\Illuminate\Foundation\Application.php(576): Illuminate\Routing\Router->dispatch(Object(Illuminate\Http\Request)) #3 E:\xampp\htdocs\basic_auth_site\vendor\laravel\framework\src\Illuminate\Foundation\Application.php(552): Illuminate\Foundation\Application->dispatch(Object(Illuminate\Http\Request)) #4 E:\xampp\htdocs\basic_auth_site\public\index.php(49): Illuminate\Foundation\Application->run() #5 {main} [] []
[2021-07-12 19:49:09] log.ERROR: Symfony\Component\HttpKernel\Exception\MethodNotAllowedHttpException in E:\xampp\htdocs\basic_auth_site\vendor\laravel\framework\src\Illuminate\Routing\Router.php:1439 Stack trace: #0 E:\xampp\htdocs\basic_auth_site\vendor\laravel\framework\src\Illuminate\Routing\Router.php(1050): Illuminate\Routing\Router->handleRoutingException(Object(Symfony\Component\Routing\Exception\MethodNotAllowedException)) #1 E:\xampp\htdocs\basic_auth_site\vendor\laravel\framework\src\Illuminate\Routing\Router.php(1014): Illuminate\Routing\Router->findRoute(Object(Illuminate\Http\Request)) #2 E:\xampp\htdocs\basic_auth_site\vendor\laravel\framework\src\Illuminate\Foundation\Application.php(576): Illuminate\Routing\Router->dispatch(Object(Illuminate\Http\Request)) #3 E:\xampp\htdocs\basic_auth_site\vendor\laravel\framework\src\Illuminate\Foundation\Application.php(552): Illuminate\Foundation\Application->dispatch(Object(Illuminate\Http\Request)) #4 E:\xampp\htdocs\basic_auth_site\public\index.php(49): Illuminate\Foundation\Application->run() #5 {main} [] []
[2021-07-12 19:49:09] log.ERROR: Symfony\Component\HttpKernel\Exception\MethodNotAllowedHttpException in E:\xampp\htdocs\basic_auth_site\vendor\laravel\framework\src\Illuminate\Routing\Router.php:1439 Stack trace: #0 E:\xampp\htdocs\basic_auth_site\vendor\laravel\framework\src\Illuminate\Routing\Router.php(1050): Illuminate\Routing\Router->handleRoutingException(Object(Symfony\Component\Routing\Exception\MethodNotAllowedException)) #1 E:\xampp\htdocs\basic_auth_site\vendor\laravel\framework\src\Illuminate\Routing\Router.php(1014): Illuminate\Routing\Router->findRoute(Object(Illuminate\Http\Request)) #2 E:\xampp\htdocs\basic_auth_site\vendor\laravel\framework\src\Illuminate\Foundation\Application.php(576): Illuminate\Routing\Router->dispatch(Object(Illuminate\Http\Request)) #3 E:\xampp\htdocs\basic_auth_site\vendor\laravel\framework\src\Illuminate\Foundation\Application.php(552): Illuminate\Foundation\Application->dispatch(Object(Illuminate\Http\Request)) #4 E:\xampp\htdocs\basic_auth_site\public\index.php(49): Illuminate\Foundation\Application->run() #5 {main} [] []
[2021-07-12 19:49:31] log.ERROR: Symfony\Component\HttpKernel\Exception\MethodNotAllowedHttpException in E:\xampp\htdocs\basic_auth_site\vendor\laravel\framework\src\Illuminate\Routing\Router.php:1439 Stack trace: #0 E:\xampp\htdocs\basic_auth_site\vendor\laravel\framework\src\Illuminate\Routing\Router.php(1050): Illuminate\Routing\Router->handleRoutingException(Object(Symfony\Component\Routing\Exception\MethodNotAllowedException)) #1 E:\xampp\htdocs\basic_auth_site\vendor\laravel\framework\src\Illuminate\Routing\Router.php(1014): Illuminate\Routing\Router->findRoute(Object(Illuminate\Http\Request)) #2 E:\xampp\htdocs\basic_auth_site\vendor\laravel\framework\src\Illuminate\Foundation\Application.php(576): Illuminate\Routing\Router->dispatch(Object(Illuminate\Http\Request)) #3 E:\xampp\htdocs\basic_auth_site\vendor\laravel\framework\src\Illuminate\Foundation\Application.php(552): Illuminate\Foundation\Application->dispatch(Object(Illuminate\Http\Request)) #4 E:\xampp\htdocs\basic_auth_site\public\index.php(49): Illuminate\Foundation\Application->run() #5 {main} [] []
[2021-07-12 19:49:32] log.ERROR: Symfony\Component\HttpKernel\Exception\MethodNotAllowedHttpException in E:\xampp\htdocs\basic_auth_site\vendor\laravel\framework\src\Illuminate\Routing\Router.php:1439 Stack trace: #0 E:\xampp\htdocs\basic_auth_site\vendor\laravel\framework\src\Illuminate\Routing\Router.php(1050): Illuminate\Routing\Router->handleRoutingException(Object(Symfony\Component\Routing\Exception\MethodNotAllowedException)) #1 E:\xampp\htdocs\basic_auth_site\vendor\laravel\framework\src\Illuminate\Routing\Router.php(1014): Illuminate\Routing\Router->findRoute(Object(Illuminate\Http\Request)) #2 E:\xampp\htdocs\basic_auth_site\vendor\laravel\framework\src\Illuminate\Foundation\Application.php(576): Illuminate\Routing\Router->dispatch(Object(Illuminate\Http\Request)) #3 E:\xampp\htdocs\basic_auth_site\vendor\laravel\framework\src\Illuminate\Foundation\Application.php(552): Illuminate\Foundation\Application->dispatch(Object(Illuminate\Http\Request)) #4 E:\xampp\htdocs\basic_auth_site\public\index.php(49): Illuminate\Foundation\Application->run() #5 {main} [] []
[2021-07-12 19:50:54] log.ERROR: Symfony\Component\HttpKernel\Exception\MethodNotAllowedHttpException in E:\xampp\htdocs\basic_auth_site\vendor\laravel\framework\src\Illuminate\Routing\Router.php:1439 Stack trace: #0 E:\xampp\htdocs\basic_auth_site\vendor\laravel\framework\src\Illuminate\Routing\Router.php(1050): Illuminate\Routing\Router->handleRoutingException(Object(Symfony\Component\Routing\Exception\MethodNotAllowedException)) #1 E:\xampp\htdocs\basic_auth_site\vendor\laravel\framework\src\Illuminate\Routing\Router.php(1014): Illuminate\Routing\Router->findRoute(Object(Illuminate\Http\Request)) #2 E:\xampp\htdocs\basic_auth_site\vendor\laravel\framework\src\Illuminate\Foundation\Application.php(576): Illuminate\Routing\Router->dispatch(Object(Illuminate\Http\Request)) #3 E:\xampp\htdocs\basic_auth_site\vendor\laravel\framework\src\Illuminate\Foundation\Application.php(552): Illuminate\Foundation\Application->dispatch(Object(Illuminate\Http\Request)) #4 E:\xampp\htdocs\basic_auth_site\public\index.php(49): Illuminate\Foundation\Application->run() #5 {main} [] []
[2021-07-12 19:50:56] log.ERROR: Symfony\Component\HttpKernel\Exception\MethodNotAllowedHttpException in E:\xampp\htdocs\basic_auth_site\vendor\laravel\framework\src\Illuminate\Routing\Router.php:1439 Stack trace: #0 E:\xampp\htdocs\basic_auth_site\vendor\laravel\framework\src\Illuminate\Routing\Router.php(1050): Illuminate\Routing\Router->handleRoutingException(Object(Symfony\Component\Routing\Exception\MethodNotAllowedException)) #1 E:\xampp\htdocs\basic_auth_site\vendor\laravel\framework\src\Illuminate\Routing\Router.php(1014): Illuminate\Routing\Router->findRoute(Object(Illuminate\Http\Request)) #2 E:\xampp\htdocs\basic_auth_site\vendor\laravel\framework\src\Illuminate\Foundation\Application.php(576): Illuminate\Routing\Router->dispatch(Object(Illuminate\Http\Request)) #3 E:\xampp\htdocs\basic_auth_site\vendor\laravel\framework\src\Illuminate\Foundation\Application.php(552): Illuminate\Foundation\Application->dispatch(Object(Illuminate\Http\Request)) #4 E:\xampp\htdocs\basic_auth_site\public\index.php(49): Illuminate\Foundation\Application->run() #5 {main} [] []
[2021-07-12 19:51:11] log.ERROR: Symfony\Component\HttpKernel\Exception\MethodNotAllowedHttpException in E:\xampp\htdocs\basic_auth_site\vendor\laravel\framework\src\Illuminate\Routing\Router.php:1439 Stack trace: #0 E:\xampp\htdocs\basic_auth_site\vendor\laravel\framework\src\Illuminate\Routing\Router.php(1050): Illuminate\Routing\Router->handleRoutingException(Object(Symfony\Component\Routing\Exception\MethodNotAllowedException)) #1 E:\xampp\htdocs\basic_auth_site\vendor\laravel\framework\src\Illuminate\Routing\Router.php(1014): Illuminate\Routing\Router->findRoute(Object(Illuminate\Http\Request)) #2 E:\xampp\htdocs\basic_auth_site\vendor\laravel\framework\src\Illuminate\Foundation\Application.php(576): Illuminate\Routing\Router->dispatch(Object(Illuminate\Http\Request)) #3 E:\xampp\htdocs\basic_auth_site\vendor\laravel\framework\src\Illuminate\Foundation\Application.php(552): Illuminate\Foundation\Application->dispatch(Object(Illuminate\Http\Request)) #4 E:\xampp\htdocs\basic_auth_site\public\index.php(49): Illuminate\Foundation\Application->run() #5 {main} [] []
[2021-07-12 19:51:22] log.ERROR: Symfony\Component\HttpKernel\Exception\MethodNotAllowedHttpException in E:\xampp\htdocs\basic_auth_site\vendor\laravel\framework\src\Illuminate\Routing\Router.php:1439 Stack trace: #0 E:\xampp\htdocs\basic_auth_site\vendor\laravel\framework\src\Illuminate\Routing\Router.php(1050): Illuminate\Routing\Router->handleRoutingException(Object(Symfony\Component\Routing\Exception\MethodNotAllowedException)) #1 E:\xampp\htdocs\basic_auth_site\vendor\laravel\framework\src\Illuminate\Routing\Router.php(1014): Illuminate\Routing\Router->findRoute(Object(Illuminate\Http\Request)) #2 E:\xampp\htdocs\basic_auth_site\vendor\laravel\framework\src\Illuminate\Foundation\Application.php(576): Illuminate\Routing\Router->dispatch(Object(Illuminate\Http\Request)) #3 E:\xampp\htdocs\basic_auth_site\vendor\laravel\framework\src\Illuminate\Foundation\Application.php(552): Illuminate\Foundation\Application->dispatch(Object(Illuminate\Http\Request)) #4 E:\xampp\htdocs\basic_auth_site\public\index.php(49): Illuminate\Foundation\Application->run() #5 {main} [] []
[2021-07-12 19:51:56] log.ERROR: Symfony\Component\HttpKernel\Exception\MethodNotAllowedHttpException in E:\xampp\htdocs\basic_auth_site\vendor\laravel\framework\src\Illuminate\Routing\Router.php:1439 Stack trace: #0 E:\xampp\htdocs\basic_auth_site\vendor\laravel\framework\src\Illuminate\Routing\Router.php(1050): Illuminate\Routing\Router->handleRoutingException(Object(Symfony\Component\Routing\Exception\MethodNotAllowedException)) #1 E:\xampp\htdocs\basic_auth_site\vendor\laravel\framework\src\Illuminate\Routing\Router.php(1014): Illuminate\Routing\Router->findRoute(Object(Illuminate\Http\Request)) #2 E:\xampp\htdocs\basic_auth_site\vendor\laravel\framework\src\Illuminate\Foundation\Application.php(576): Illuminate\Routing\Router->dispatch(Object(Illuminate\Http\Request)) #3 E:\xampp\htdocs\basic_auth_site\vendor\laravel\framework\src\Illuminate\Foundation\Application.php(552): Illuminate\Foundation\Application->dispatch(Object(Illuminate\Http\Request)) #4 E:\xampp\htdocs\basic_auth_site\public\index.php(49): Illuminate\Foundation\Application->run() #5 {main} [] []
[2021-07-12 19:52:00] log.ERROR: Symfony\Component\HttpKernel\Exception\MethodNotAllowedHttpException in E:\xampp\htdocs\basic_auth_site\vendor\laravel\framework\src\Illuminate\Routing\Router.php:1439 Stack trace: #0 E:\xampp\htdocs\basic_auth_site\vendor\laravel\framework\src\Illuminate\Routing\Router.php(1050): Illuminate\Routing\Router->handleRoutingException(Object(Symfony\Component\Routing\Exception\MethodNotAllowedException)) #1 E:\xampp\htdocs\basic_auth_site\vendor\laravel\framework\src\Illuminate\Routing\Router.php(1014): Illuminate\Routing\Router->findRoute(Object(Illuminate\Http\Request)) #2 E:\xampp\htdocs\basic_auth_site\vendor\laravel\framework\src\Illuminate\Foundation\Application.php(576): Illuminate\Routing\Router->dispatch(Object(Illuminate\Http\Request)) #3 E:\xampp\htdocs\basic_auth_site\vendor\laravel\framework\src\Illuminate\Foundation\Application.php(552): Illuminate\Foundation\Application->dispatch(Object(Illuminate\Http\Request)) #4 E:\xampp\htdocs\basic_auth_site\public\index.php(49): Illuminate\Foundation\Application->run() #5 {main} [] []
[2021-07-12 19:52:43] log.ERROR: Symfony\Component\HttpKernel\Exception\MethodNotAllowedHttpException in E:\xampp\htdocs\basic_auth_site\vendor\laravel\framework\src\Illuminate\Routing\Router.php:1439 Stack trace: #0 E:\xampp\htdocs\basic_auth_site\vendor\laravel\framework\src\Illuminate\Routing\Router.php(1050): Illuminate\Routing\Router->handleRoutingException(Object(Symfony\Component\Routing\Exception\MethodNotAllowedException)) #1 E:\xampp\htdocs\basic_auth_site\vendor\laravel\framework\src\Illuminate\Routing\Router.php(1014): Illuminate\Routing\Router->findRoute(Object(Illuminate\Http\Request)) #2 E:\xampp\htdocs\basic_auth_site\vendor\laravel\framework\src\Illuminate\Foundation\Application.php(576): Illuminate\Routing\Router->dispatch(Object(Illuminate\Http\Request)) #3 E:\xampp\htdocs\basic_auth_site\vendor\laravel\framework\src\Illuminate\Foundation\Application.php(552): Illuminate\Foundation\Application->dispatch(Object(Illuminate\Http\Request)) #4 E:\xampp\htdocs\basic_auth_site\public\index.php(49): Illuminate\Foundation\Application->run() #5 {main} [] []
[2021-07-12 19:54:13] log.ERROR: Symfony\Component\HttpKernel\Exception\MethodNotAllowedHttpException in E:\xampp\htdocs\basic_auth_site\vendor\laravel\framework\src\Illuminate\Routing\Router.php:1439 Stack trace: #0 E:\xampp\htdocs\basic_auth_site\vendor\laravel\framework\src\Illuminate\Routing\Router.php(1050): Illuminate\Routing\Router->handleRoutingException(Object(Symfony\Component\Routing\Exception\MethodNotAllowedException)) #1 E:\xampp\htdocs\basic_auth_site\vendor\laravel\framework\src\Illuminate\Routing\Router.php(1014): Illuminate\Routing\Router->findRoute(Object(Illuminate\Http\Request)) #2 E:\xampp\htdocs\basic_auth_site\vendor\laravel\framework\src\Illuminate\Foundation\Application.php(576): Illuminate\Routing\Router->dispatch(Object(Illuminate\Http\Request)) #3 E:\xampp\htdocs\basic_auth_site\vendor\laravel\framework\src\Illuminate\Foundation\Application.php(552): Illuminate\Foundation\Application->dispatch(Object(Illuminate\Http\Request)) #4 E:\xampp\htdocs\basic_auth_site\public\index.php(49): Illuminate\Foundation\Application->run() #5 {main} [] []
[2021-07-12 19:54:22] log.ERROR: Symfony\Component\HttpKernel\Exception\MethodNotAllowedHttpException in E:\xampp\htdocs\basic_auth_site\vendor\laravel\framework\src\Illuminate\Routing\Router.php:1439 Stack trace: #0 E:\xampp\htdocs\basic_auth_site\vendor\laravel\framework\src\Illuminate\Routing\Router.php(1050): Illuminate\Routing\Router->handleRoutingException(Object(Symfony\Component\Routing\Exception\MethodNotAllowedException)) #1 E:\xampp\htdocs\basic_auth_site\vendor\laravel\framework\src\Illuminate\Routing\Router.php(1014): Illuminate\Routing\Router->findRoute(Object(Illuminate\Http\Request)) #2 E:\xampp\htdocs\basic_auth_site\vendor\laravel\framework\src\Illuminate\Foundation\Application.php(576): Illuminate\Routing\Router->dispatch(Object(Illuminate\Http\Request)) #3 E:\xampp\htdocs\basic_auth_site\vendor\laravel\framework\src\Illuminate\Foundation\Application.php(552): Illuminate\Foundation\Application->dispatch(Object(Illuminate\Http\Request)) #4 E:\xampp\htdocs\basic_auth_site\public\index.php(49): Illuminate\Foundation\Application->run() #5 {main} [] []
[2021-07-12 19:54:29] log.ERROR: Symfony\Component\HttpKernel\Exception\MethodNotAllowedHttpException in E:\xampp\htdocs\basic_auth_site\vendor\laravel\framework\src\Illuminate\Routing\Router.php:1439 Stack trace: #0 E:\xampp\htdocs\basic_auth_site\vendor\laravel\framework\src\Illuminate\Routing\Router.php(1050): Illuminate\Routing\Router->handleRoutingException(Object(Symfony\Component\Routing\Exception\MethodNotAllowedException)) #1 E:\xampp\htdocs\basic_auth_site\vendor\laravel\framework\src\Illuminate\Routing\Router.php(1014): Illuminate\Routing\Router->findRoute(Object(Illuminate\Http\Request)) #2 E:\xampp\htdocs\basic_auth_site\vendor\laravel\framework\src\Illuminate\Foundation\Application.php(576): Illuminate\Routing\Router->dispatch(Object(Illuminate\Http\Request)) #3 E:\xampp\htdocs\basic_auth_site\vendor\laravel\framework\src\Illuminate\Foundation\Application.php(552): Illuminate\Foundation\Application->dispatch(Object(Illuminate\Http\Request)) #4 E:\xampp\htdocs\basic_auth_site\public\index.php(49): Illuminate\Foundation\Application->run() #5 {main} [] []
[2021-07-12 19:54:31] log.ERROR: Symfony\Component\HttpKernel\Exception\MethodNotAllowedHttpException in E:\xampp\htdocs\basic_auth_site\vendor\laravel\framework\src\Illuminate\Routing\Router.php:1439 Stack trace: #0 E:\xampp\htdocs\basic_auth_site\vendor\laravel\framework\src\Illuminate\Routing\Router.php(1050): Illuminate\Routing\Router->handleRoutingException(Object(Symfony\Component\Routing\Exception\MethodNotAllowedException)) #1 E:\xampp\htdocs\basic_auth_site\vendor\laravel\framework\src\Illuminate\Routing\Router.php(1014): Illuminate\Routing\Router->findRoute(Object(Illuminate\Http\Request)) #2 E:\xampp\htdocs\basic_auth_site\vendor\laravel\framework\src\Illuminate\Foundation\Application.php(576): Illuminate\Routing\Router->dispatch(Object(Illuminate\Http\Request)) #3 E:\xampp\htdocs\basic_auth_site\vendor\laravel\framework\src\Illuminate\Foundation\Application.php(552): Illuminate\Foundation\Application->dispatch(Object(Illuminate\Http\Request)) #4 E:\xampp\htdocs\basic_auth_site\public\index.php(49): Illuminate\Foundation\Application->run() #5 {main} [] []
[2021-07-12 19:54:38] log.ERROR: Symfony\Component\HttpKernel\Exception\MethodNotAllowedHttpException in E:\xampp\htdocs\basic_auth_site\vendor\laravel\framework\src\Illuminate\Routing\Router.php:1439 Stack trace: #0 E:\xampp\htdocs\basic_auth_site\vendor\laravel\framework\src\Illuminate\Routing\Router.php(1050): Illuminate\Routing\Router->handleRoutingException(Object(Symfony\Component\Routing\Exception\MethodNotAllowedException)) #1 E:\xampp\htdocs\basic_auth_site\vendor\laravel\framework\src\Illuminate\Routing\Router.php(1014): Illuminate\Routing\Router->findRoute(Object(Illuminate\Http\Request)) #2 E:\xampp\htdocs\basic_auth_site\vendor\laravel\framework\src\Illuminate\Foundation\Application.php(576): Illuminate\Routing\Router->dispatch(Object(Illuminate\Http\Request)) #3 E:\xampp\htdocs\basic_auth_site\vendor\laravel\framework\src\Illuminate\Foundation\Application.php(552): Illuminate\Foundation\Application->dispatch(Object(Illuminate\Http\Request)) #4 E:\xampp\htdocs\basic_auth_site\public\index.php(49): Illuminate\Foundation\Application->run() #5 {main} [] []
[2021-07-12 19:54:39] log.ERROR: Symfony\Component\HttpKernel\Exception\MethodNotAllowedHttpException in E:\xampp\htdocs\basic_auth_site\vendor\laravel\framework\src\Illuminate\Routing\Router.php:1439 Stack trace: #0 E:\xampp\htdocs\basic_auth_site\vendor\laravel\framework\src\Illuminate\Routing\Router.php(1050): Illuminate\Routing\Router->handleRoutingException(Object(Symfony\Component\Routing\Exception\MethodNotAllowedException)) #1 E:\xampp\htdocs\basic_auth_site\vendor\laravel\framework\src\Illuminate\Routing\Router.php(1014): Illuminate\Routing\Router->findRoute(Object(Illuminate\Http\Request)) #2 E:\xampp\htdocs\basic_auth_site\vendor\laravel\framework\src\Illuminate\Foundation\Application.php(576): Illuminate\Routing\Router->dispatch(Object(Illuminate\Http\Request)) #3 E:\xampp\htdocs\basic_auth_site\vendor\laravel\framework\src\Illuminate\Foundation\Application.php(552): Illuminate\Foundation\Application->dispatch(Object(Illuminate\Http\Request)) #4 E:\xampp\htdocs\basic_auth_site\public\index.php(49): Illuminate\Foundation\Application->run() #5 {main} [] []
[2021-07-12 19:54:40] log.ERROR: Symfony\Component\HttpKernel\Exception\MethodNotAllowedHttpException in E:\xampp\htdocs\basic_auth_site\vendor\laravel\framework\src\Illuminate\Routing\Router.php:1439 Stack trace: #0 E:\xampp\htdocs\basic_auth_site\vendor\laravel\framework\src\Illuminate\Routing\Router.php(1050): Illuminate\Routing\Router->handleRoutingException(Object(Symfony\Component\Routing\Exception\MethodNotAllowedException)) #1 E:\xampp\htdocs\basic_auth_site\vendor\laravel\framework\src\Illuminate\Routing\Router.php(1014): Illuminate\Routing\Router->findRoute(Object(Illuminate\Http\Request)) #2 E:\xampp\htdocs\basic_auth_site\vendor\laravel\framework\src\Illuminate\Foundation\Application.php(576): Illuminate\Routing\Router->dispatch(Object(Illuminate\Http\Request)) #3 E:\xampp\htdocs\basic_auth_site\vendor\laravel\framework\src\Illuminate\Foundation\Application.php(552): Illuminate\Foundation\Application->dispatch(Object(Illuminate\Http\Request)) #4 E:\xampp\htdocs\basic_auth_site\public\index.php(49): Illuminate\Foundation\Application->run() #5 {main} [] []
[2021-07-12 19:54:54] log.ERROR: Symfony\Component\HttpKernel\Exception\MethodNotAllowedHttpException in E:\xampp\htdocs\basic_auth_site\vendor\laravel\framework\src\Illuminate\Routing\Router.php:1439 Stack trace: #0 E:\xampp\htdocs\basic_auth_site\vendor\laravel\framework\src\Illuminate\Routing\Router.php(1050): Illuminate\Routing\Router->handleRoutingException(Object(Symfony\Component\Routing\Exception\MethodNotAllowedException)) #1 E:\xampp\htdocs\basic_auth_site\vendor\laravel\framework\src\Illuminate\Routing\Router.php(1014): Illuminate\Routing\Router->findRoute(Object(Illuminate\Http\Request)) #2 E:\xampp\htdocs\basic_auth_site\vendor\laravel\framework\src\Illuminate\Foundation\Application.php(576): Illuminate\Routing\Router->dispatch(Object(Illuminate\Http\Request)) #3 E:\xampp\htdocs\basic_auth_site\vendor\laravel\framework\src\Illuminate\Foundation\Application.php(552): Illuminate\Foundation\Application->dispatch(Object(Illuminate\Http\Request)) #4 E:\xampp\htdocs\basic_auth_site\public\index.php(49): Illuminate\Foundation\Application->run() #5 {main} [] []
[2021-07-12 19:54:59] log.ERROR: Symfony\Component\HttpKernel\Exception\MethodNotAllowedHttpException in E:\xampp\htdocs\basic_auth_site\vendor\laravel\framework\src\Illuminate\Routing\Router.php:1439 Stack trace: #0 E:\xampp\htdocs\basic_auth_site\vendor\laravel\framework\src\Illuminate\Routing\Router.php(1050): Illuminate\Routing\Router->handleRoutingException(Object(Symfony\Component\Routing\Exception\MethodNotAllowedException)) #1 E:\xampp\htdocs\basic_auth_site\vendor\laravel\framework\src\Illuminate\Routing\Router.php(1014): Illuminate\Routing\Router->findRoute(Object(Illuminate\Http\Request)) #2 E:\xampp\htdocs\basic_auth_site\vendor\laravel\framework\src\Illuminate\Foundation\Application.php(576): Illuminate\Routing\Router->dispatch(Object(Illuminate\Http\Request)) #3 E:\xampp\htdocs\basic_auth_site\vendor\laravel\framework\src\Illuminate\Foundation\Application.php(552): Illuminate\Foundation\Application->dispatch(Object(Illuminate\Http\Request)) #4 E:\xampp\htdocs\basic_auth_site\public\index.php(49): Illuminate\Foundation\Application->run() #5 {main} [] []
[2021-07-12 19:55:04] log.ERROR: Symfony\Component\HttpKernel\Exception\MethodNotAllowedHttpException in E:\xampp\htdocs\basic_auth_site\vendor\laravel\framework\src\Illuminate\Routing\Router.php:1439 Stack trace: #0 E:\xampp\htdocs\basic_auth_site\vendor\laravel\framework\src\Illuminate\Routing\Router.php(1050): Illuminate\Routing\Router->handleRoutingException(Object(Symfony\Component\Routing\Exception\MethodNotAllowedException)) #1 E:\xampp\htdocs\basic_auth_site\vendor\laravel\framework\src\Illuminate\Routing\Router.php(1014): Illuminate\Routing\Router->findRoute(Object(Illuminate\Http\Request)) #2 E:\xampp\htdocs\basic_auth_site\vendor\laravel\framework\src\Illuminate\Foundation\Application.php(576): Illuminate\Routing\Router->dispatch(Object(Illuminate\Http\Request)) #3 E:\xampp\htdocs\basic_auth_site\vendor\laravel\framework\src\Illuminate\Foundation\Application.php(552): Illuminate\Foundation\Application->dispatch(Object(Illuminate\Http\Request)) #4 E:\xampp\htdocs\basic_auth_site\public\index.php(49): Illuminate\Foundation\Application->run() #5 {main} [] []
[2021-07-12 19:55:06] log.ERROR: Symfony\Component\HttpKernel\Exception\MethodNotAllowedHttpException in E:\xampp\htdocs\basic_auth_site\vendor\laravel\framework\src\Illuminate\Routing\Router.php:1439 Stack trace: #0 E:\xampp\htdocs\basic_auth_site\vendor\laravel\framework\src\Illuminate\Routing\Router.php(1050): Illuminate\Routing\Router->handleRoutingException(Object(Symfony\Component\Routing\Exception\MethodNotAllowedException)) #1 E:\xampp\htdocs\basic_auth_site\vendor\laravel\framework\src\Illuminate\Routing\Router.php(1014): Illuminate\Routing\Router->findRoute(Object(Illuminate\Http\Request)) #2 E:\xampp\htdocs\basic_auth_site\vendor\laravel\framework\src\Illuminate\Foundation\Application.php(576): Illuminate\Routing\Router->dispatch(Object(Illuminate\Http\Request)) #3 E:\xampp\htdocs\basic_auth_site\vendor\laravel\framework\src\Illuminate\Foundation\Application.php(552): Illuminate\Foundation\Application->dispatch(Object(Illuminate\Http\Request)) #4 E:\xampp\htdocs\basic_auth_site\public\index.php(49): Illuminate\Foundation\Application->run() #5 {main} [] []
[2021-07-12 19:55:18] log.ERROR: Symfony\Component\HttpKernel\Exception\MethodNotAllowedHttpException in E:\xampp\htdocs\basic_auth_site\vendor\laravel\framework\src\Illuminate\Routing\Router.php:1439 Stack trace: #0 E:\xampp\htdocs\basic_auth_site\vendor\laravel\framework\src\Illuminate\Routing\Router.php(1050): Illuminate\Routing\Router->handleRoutingException(Object(Symfony\Component\Routing\Exception\MethodNotAllowedException)) #1 E:\xampp\htdocs\basic_auth_site\vendor\laravel\framework\src\Illuminate\Routing\Router.php(1014): Illuminate\Routing\Router->findRoute(Object(Illuminate\Http\Request)) #2 E:\xampp\htdocs\basic_auth_site\vendor\laravel\framework\src\Illuminate\Foundation\Application.php(576): Illuminate\Routing\Router->dispatch(Object(Illuminate\Http\Request)) #3 E:\xampp\htdocs\basic_auth_site\vendor\laravel\framework\src\Illuminate\Foundation\Application.php(552): Illuminate\Foundation\Application->dispatch(Object(Illuminate\Http\Request)) #4 E:\xampp\htdocs\basic_auth_site\public\index.php(49): Illuminate\Foundation\Application->run() #5 {main} [] []
[2021-07-12 19:55:27] log.ERROR: Symfony\Component\HttpKernel\Exception\MethodNotAllowedHttpException in E:\xampp\htdocs\basic_auth_site\vendor\laravel\framework\src\Illuminate\Routing\Router.php:1439 Stack trace: #0 E:\xampp\htdocs\basic_auth_site\vendor\laravel\framework\src\Illuminate\Routing\Router.php(1050): Illuminate\Routing\Router->handleRoutingException(Object(Symfony\Component\Routing\Exception\MethodNotAllowedException)) #1 E:\xampp\htdocs\basic_auth_site\vendor\laravel\framework\src\Illuminate\Routing\Router.php(1014): Illuminate\Routing\Router->findRoute(Object(Illuminate\Http\Request)) #2 E:\xampp\htdocs\basic_auth_site\vendor\laravel\framework\src\Illuminate\Foundation\Application.php(576): Illuminate\Routing\Router->dispatch(Object(Illuminate\Http\Request)) #3 E:\xampp\htdocs\basic_auth_site\vendor\laravel\framework\src\Illuminate\Foundation\Application.php(552): Illuminate\Foundation\Application->dispatch(Object(Illuminate\Http\Request)) #4 E:\xampp\htdocs\basic_auth_site\public\index.php(49): Illuminate\Foundation\Application->run() #5 {main} [] []
[2021-07-12 19:55:36] log.ERROR: Symfony\Component\HttpKernel\Exception\MethodNotAllowedHttpException in E:\xampp\htdocs\basic_auth_site\vendor\laravel\framework\src\Illuminate\Routing\Router.php:1439 Stack trace: #0 E:\xampp\htdocs\basic_auth_site\vendor\laravel\framework\src\Illuminate\Routing\Router.php(1050): Illuminate\Routing\Router->handleRoutingException(Object(Symfony\Component\Routing\Exception\MethodNotAllowedException)) #1 E:\xampp\htdocs\basic_auth_site\vendor\laravel\framework\src\Illuminate\Routing\Router.php(1014): Illuminate\Routing\Router->findRoute(Object(Illuminate\Http\Request)) #2 E:\xampp\htdocs\basic_auth_site\vendor\laravel\framework\src\Illuminate\Foundation\Application.php(576): Illuminate\Routing\Router->dispatch(Object(Illuminate\Http\Request)) #3 E:\xampp\htdocs\basic_auth_site\vendor\laravel\framework\src\Illuminate\Foundation\Application.php(552): Illuminate\Foundation\Application->dispatch(Object(Illuminate\Http\Request)) #4 E:\xampp\htdocs\basic_auth_site\public\index.php(49): Illuminate\Foundation\Application->run() #5 {main} [] []
[2021-07-12 19:56:21] log.ERROR: Symfony\Component\HttpKernel\Exception\MethodNotAllowedHttpException in E:\xampp\htdocs\basic_auth_site\vendor\laravel\framework\src\Illuminate\Routing\Router.php:1439 Stack trace: #0 E:\xampp\htdocs\basic_auth_site\vendor\laravel\framework\src\Illuminate\Routing\Router.php(1050): Illuminate\Routing\Router->handleRoutingException(Object(Symfony\Component\Routing\Exception\MethodNotAllowedException)) #1 E:\xampp\htdocs\basic_auth_site\vendor\laravel\framework\src\Illuminate\Routing\Router.php(1014): Illuminate\Routing\Router->findRoute(Object(Illuminate\Http\Request)) #2 E:\xampp\htdocs\basic_auth_site\vendor\laravel\framework\src\Illuminate\Foundation\Application.php(576): Illuminate\Routing\Router->dispatch(Object(Illuminate\Http\Request)) #3 E:\xampp\htdocs\basic_auth_site\vendor\laravel\framework\src\Illuminate\Foundation\Application.php(552): Illuminate\Foundation\Application->dispatch(Object(Illuminate\Http\Request)) #4 E:\xampp\htdocs\basic_auth_site\public\index.php(49): Illuminate\Foundation\Application->run() #5 {main} [] []
[2021-07-12 19:56:22] log.ERROR: Symfony\Component\HttpKernel\Exception\MethodNotAllowedHttpException in E:\xampp\htdocs\basic_auth_site\vendor\laravel\framework\src\Illuminate\Routing\Router.php:1439 Stack trace: #0 E:\xampp\htdocs\basic_auth_site\vendor\laravel\framework\src\Illuminate\Routing\Router.php(1050): Illuminate\Routing\Router->handleRoutingException(Object(Symfony\Component\Routing\Exception\MethodNotAllowedException)) #1 E:\xampp\htdocs\basic_auth_site\vendor\laravel\framework\src\Illuminate\Routing\Router.php(1014): Illuminate\Routing\Router->findRoute(Object(Illuminate\Http\Request)) #2 E:\xampp\htdocs\basic_auth_site\vendor\laravel\framework\src\Illuminate\Foundation\Application.php(576): Illuminate\Routing\Router->dispatch(Object(Illuminate\Http\Request)) #3 E:\xampp\htdocs\basic_auth_site\vendor\laravel\framework\src\Illuminate\Foundation\Application.php(552): Illuminate\Foundation\Application->dispatch(Object(Illuminate\Http\Request)) #4 E:\xampp\htdocs\basic_auth_site\public\index.php(49): Illuminate\Foundation\Application->run() #5 {main} [] []
[2021-07-12 19:56:26] log.ERROR: Symfony\Component\HttpKernel\Exception\MethodNotAllowedHttpException in E:\xampp\htdocs\basic_auth_site\vendor\laravel\framework\src\Illuminate\Routing\Router.php:1439 Stack trace: #0 E:\xampp\htdocs\basic_auth_site\vendor\laravel\framework\src\Illuminate\Routing\Router.php(1050): Illuminate\Routing\Router->handleRoutingException(Object(Symfony\Component\Routing\Exception\MethodNotAllowedException)) #1 E:\xampp\htdocs\basic_auth_site\vendor\laravel\framework\src\Illuminate\Routing\Router.php(1014): Illuminate\Routing\Router->findRoute(Object(Illuminate\Http\Request)) #2 E:\xampp\htdocs\basic_auth_site\vendor\laravel\framework\src\Illuminate\Foundation\Application.php(576): Illuminate\Routing\Router->dispatch(Object(Illuminate\Http\Request)) #3 E:\xampp\htdocs\basic_auth_site\vendor\laravel\framework\src\Illuminate\Foundation\Application.php(552): Illuminate\Foundation\Application->dispatch(Object(Illuminate\Http\Request)) #4 E:\xampp\htdocs\basic_auth_site\public\index.php(49): Illuminate\Foundation\Application->run() #5 {main} [] []
[2021-07-12 19:56:52] log.ERROR: Symfony\Component\HttpKernel\Exception\MethodNotAllowedHttpException in E:\xampp\htdocs\basic_auth_site\vendor\laravel\framework\src\Illuminate\Routing\Router.php:1439 Stack trace: #0 E:\xampp\htdocs\basic_auth_site\vendor\laravel\framework\src\Illuminate\Routing\Router.php(1050): Illuminate\Routing\Router->handleRoutingException(Object(Symfony\Component\Routing\Exception\MethodNotAllowedException)) #1 E:\xampp\htdocs\basic_auth_site\vendor\laravel\framework\src\Illuminate\Routing\Router.php(1014): Illuminate\Routing\Router->findRoute(Object(Illuminate\Http\Request)) #2 E:\xampp\htdocs\basic_auth_site\vendor\laravel\framework\src\Illuminate\Foundation\Application.php(576): Illuminate\Routing\Router->dispatch(Object(Illuminate\Http\Request)) #3 E:\xampp\htdocs\basic_auth_site\vendor\laravel\framework\src\Illuminate\Foundation\Application.php(552): Illuminate\Foundation\Application->dispatch(Object(Illuminate\Http\Request)) #4 E:\xampp\htdocs\basic_auth_site\public\index.php(49): Illuminate\Foundation\Application->run() #5 {main} [] []
[2021-07-12 19:57:24] log.ERROR: Symfony\Component\HttpKernel\Exception\MethodNotAllowedHttpException in E:\xampp\htdocs\basic_auth_site\vendor\laravel\framework\src\Illuminate\Routing\Router.php:1439 Stack trace: #0 E:\xampp\htdocs\basic_auth_site\vendor\laravel\framework\src\Illuminate\Routing\Router.php(1050): Illuminate\Routing\Router->handleRoutingException(Object(Symfony\Component\Routing\Exception\MethodNotAllowedException)) #1 E:\xampp\htdocs\basic_auth_site\vendor\laravel\framework\src\Illuminate\Routing\Router.php(1014): Illuminate\Routing\Router->findRoute(Object(Illuminate\Http\Request)) #2 E:\xampp\htdocs\basic_auth_site\vendor\laravel\framework\src\Illuminate\Foundation\Application.php(576): Illuminate\Routing\Router->dispatch(Object(Illuminate\Http\Request)) #3 E:\xampp\htdocs\basic_auth_site\vendor\laravel\framework\src\Illuminate\Foundation\Application.php(552): Illuminate\Foundation\Application->dispatch(Object(Illuminate\Http\Request)) #4 E:\xampp\htdocs\basic_auth_site\public\index.php(49): Illuminate\Foundation\Application->run() #5 {main} [] []
[2021-07-12 19:57:29] log.ERROR: Symfony\Component\HttpKernel\Exception\MethodNotAllowedHttpException in E:\xampp\htdocs\basic_auth_site\vendor\laravel\framework\src\Illuminate\Routing\Router.php:1439 Stack trace: #0 E:\xampp\htdocs\basic_auth_site\vendor\laravel\framework\src\Illuminate\Routing\Router.php(1050): Illuminate\Routing\Router->handleRoutingException(Object(Symfony\Component\Routing\Exception\MethodNotAllowedException)) #1 E:\xampp\htdocs\basic_auth_site\vendor\laravel\framework\src\Illuminate\Routing\Router.php(1014): Illuminate\Routing\Router->findRoute(Object(Illuminate\Http\Request)) #2 E:\xampp\htdocs\basic_auth_site\vendor\laravel\framework\src\Illuminate\Foundation\Application.php(576): Illuminate\Routing\Router->dispatch(Object(Illuminate\Http\Request)) #3 E:\xampp\htdocs\basic_auth_site\vendor\laravel\framework\src\Illuminate\Foundation\Application.php(552): Illuminate\Foundation\Application->dispatch(Object(Illuminate\Http\Request)) #4 E:\xampp\htdocs\basic_auth_site\public\index.php(49): Illuminate\Foundation\Application->run() #5 {main} [] []
[2021-07-12 19:57:48] log.ERROR: Symfony\Component\HttpKernel\Exception\MethodNotAllowedHttpException in E:\xampp\htdocs\basic_auth_site\vendor\laravel\framework\src\Illuminate\Routing\Router.php:1439 Stack trace: #0 E:\xampp\htdocs\basic_auth_site\vendor\laravel\framework\src\Illuminate\Routing\Router.php(1050): Illuminate\Routing\Router->handleRoutingException(Object(Symfony\Component\Routing\Exception\MethodNotAllowedException)) #1 E:\xampp\htdocs\basic_auth_site\vendor\laravel\framework\src\Illuminate\Routing\Router.php(1014): Illuminate\Routing\Router->findRoute(Object(Illuminate\Http\Request)) #2 E:\xampp\htdocs\basic_auth_site\vendor\laravel\framework\src\Illuminate\Foundation\Application.php(576): Illuminate\Routing\Router->dispatch(Object(Illuminate\Http\Request)) #3 E:\xampp\htdocs\basic_auth_site\vendor\laravel\framework\src\Illuminate\Foundation\Application.php(552): Illuminate\Foundation\Application->dispatch(Object(Illuminate\Http\Request)) #4 E:\xampp\htdocs\basic_auth_site\public\index.php(49): Illuminate\Foundation\Application->run() #5 {main} [] []
[2021-07-12 19:58:41] log.ERROR: Symfony\Component\HttpKernel\Exception\MethodNotAllowedHttpException in E:\xampp\htdocs\basic_auth_site\vendor\laravel\framework\src\Illuminate\Routing\Router.php:1439 Stack trace: #0 E:\xampp\htdocs\basic_auth_site\vendor\laravel\framework\src\Illuminate\Routing\Router.php(1050): Illuminate\Routing\Router->handleRoutingException(Object(Symfony\Component\Routing\Exception\MethodNotAllowedException)) #1 E:\xampp\htdocs\basic_auth_site\vendor\laravel\framework\src\Illuminate\Routing\Router.php(1014): Illuminate\Routing\Router->findRoute(Object(Illuminate\Http\Request)) #2 E:\xampp\htdocs\basic_auth_site\vendor\laravel\framework\src\Illuminate\Foundation\Application.php(576): Illuminate\Routing\Router->dispatch(Object(Illuminate\Http\Request)) #3 E:\xampp\htdocs\basic_auth_site\vendor\laravel\framework\src\Illuminate\Foundation\Application.php(552): Illuminate\Foundation\Application->dispatch(Object(Illuminate\Http\Request)) #4 E:\xampp\htdocs\basic_auth_site\public\index.php(49): Illuminate\Foundation\Application->run() #5 {main} [] []
[2021-07-12 19:59:38] log.ERROR: Symfony\Component\HttpKernel\Exception\NotFoundHttpException in E:\xampp\htdocs\basic_auth_site\vendor\laravel\framework\src\Illuminate\Routing\Router.php:1429 Stack trace: #0 E:\xampp\htdocs\basic_auth_site\vendor\laravel\framework\src\Illuminate\Routing\Router.php(1050): Illuminate\Routing\Router->handleRoutingException(Object(Symfony\Component\Routing\Exception\ResourceNotFoundException)) #1 E:\xampp\htdocs\basic_auth_site\vendor\laravel\framework\src\Illuminate\Routing\Router.php(1014): Illuminate\Routing\Router->findRoute(Object(Illuminate\Http\Request)) #2 E:\xampp\htdocs\basic_auth_site\vendor\laravel\framework\src\Illuminate\Foundation\Application.php(576): Illuminate\Routing\Router->dispatch(Object(Illuminate\Http\Request)) #3 E:\xampp\htdocs\basic_auth_site\vendor\laravel\framework\src\Illuminate\Foundation\Application.php(552): Illuminate\Foundation\Application->dispatch(Object(Illuminate\Http\Request)) #4 E:\xampp\htdocs\basic_auth_site\public\index.php(49): Illuminate\Foundation\Application->run() #5 {main} [] []
[2021-07-12 20:02:05] log.ERROR: Symfony\Component\Debug\Exception\FatalErrorException: Uncaught TypeError: Argument 1 passed to Illuminate\Exception\WhoopsDisplayer::display() must be an instance of Exception, instance of ParseError given, called in E:\xampp\htdocs\basic_auth_site\vendor\laravel\framework\src\Illuminate\Exception\Handler.php on line 275 and defined in E:\xampp\htdocs\basic_auth_site\vendor\laravel\framework\src\Illuminate\Exception\WhoopsDisplayer.php:40 Stack trace: #0 E:\xampp\htdocs\basic_auth_site\vendor\laravel\framework\src\Illuminate\Exception\Handler.php(275): Illuminate\Exception\WhoopsDisplayer->display(Object(ParseError)) #1 E:\xampp\htdocs\basic_auth_site\vendor\laravel\framework\src\Illuminate\Exception\Handler.php(162): Illuminate\Exception\Handler->displayException(Object(ParseError)) #2 [internal function]: Illuminate\Exception\Handler->handleException(Object(ParseError)) #3 {main}   thrown in E:\xampp\htdocs\basic_auth_site\vendor\laravel\framework\src\Illuminate\Exception\WhoopsDisplayer.php:40 Stack trace: #0 [internal function]: Illuminate\Exception\Handler->handleShutdown() #1 {main} [] []
[2021-07-12 20:02:07] log.ERROR: Symfony\Component\Debug\Exception\FatalErrorException: Uncaught TypeError: Argument 1 passed to Illuminate\Exception\WhoopsDisplayer::display() must be an instance of Exception, instance of ParseError given, called in E:\xampp\htdocs\basic_auth_site\vendor\laravel\framework\src\Illuminate\Exception\Handler.php on line 275 and defined in E:\xampp\htdocs\basic_auth_site\vendor\laravel\framework\src\Illuminate\Exception\WhoopsDisplayer.php:40 Stack trace: #0 E:\xampp\htdocs\basic_auth_site\vendor\laravel\framework\src\Illuminate\Exception\Handler.php(275): Illuminate\Exception\WhoopsDisplayer->display(Object(ParseError)) #1 E:\xampp\htdocs\basic_auth_site\vendor\laravel\framework\src\Illuminate\Exception\Handler.php(162): Illuminate\Exception\Handler->displayException(Object(ParseError)) #2 [internal function]: Illuminate\Exception\Handler->handleException(Object(ParseError)) #3 {main}   thrown in E:\xampp\htdocs\basic_auth_site\vendor\laravel\framework\src\Illuminate\Exception\WhoopsDisplayer.php:40 Stack trace: #0 [internal function]: Illuminate\Exception\Handler->handleShutdown() #1 {main} [] []
[2021-07-12 20:02:08] log.ERROR: Symfony\Component\Debug\Exception\FatalErrorException: Uncaught TypeError: Argument 1 passed to Illuminate\Exception\WhoopsDisplayer::display() must be an instance of Exception, instance of ParseError given, called in E:\xampp\htdocs\basic_auth_site\vendor\laravel\framework\src\Illuminate\Exception\Handler.php on line 275 and defined in E:\xampp\htdocs\basic_auth_site\vendor\laravel\framework\src\Illuminate\Exception\WhoopsDisplayer.php:40 Stack trace: #0 E:\xampp\htdocs\basic_auth_site\vendor\laravel\framework\src\Illuminate\Exception\Handler.php(275): Illuminate\Exception\WhoopsDisplayer->display(Object(ParseError)) #1 E:\xampp\htdocs\basic_auth_site\vendor\laravel\framework\src\Illuminate\Exception\Handler.php(162): Illuminate\Exception\Handler->displayException(Object(ParseError)) #2 [internal function]: Illuminate\Exception\Handler->handleException(Object(ParseError)) #3 {main}   thrown in E:\xampp\htdocs\basic_auth_site\vendor\laravel\framework\src\Illuminate\Exception\WhoopsDisplayer.php:40 Stack trace: #0 [internal function]: Illuminate\Exception\Handler->handleShutdown() #1 {main} [] []
[2021-07-12 20:02:10] log.ERROR: Symfony\Component\Debug\Exception\FatalErrorException: Uncaught TypeError: Argument 1 passed to Illuminate\Exception\WhoopsDisplayer::display() must be an instance of Exception, instance of ParseError given, called in E:\xampp\htdocs\basic_auth_site\vendor\laravel\framework\src\Illuminate\Exception\Handler.php on line 275 and defined in E:\xampp\htdocs\basic_auth_site\vendor\laravel\framework\src\Illuminate\Exception\WhoopsDisplayer.php:40 Stack trace: #0 E:\xampp\htdocs\basic_auth_site\vendor\laravel\framework\src\Illuminate\Exception\Handler.php(275): Illuminate\Exception\WhoopsDisplayer->display(Object(ParseError)) #1 E:\xampp\htdocs\basic_auth_site\vendor\laravel\framework\src\Illuminate\Exception\Handler.php(162): Illuminate\Exception\Handler->displayException(Object(ParseError)) #2 [internal function]: Illuminate\Exception\Handler->handleException(Object(ParseError)) #3 {main}   thrown in E:\xampp\htdocs\basic_auth_site\vendor\laravel\framework\src\Illuminate\Exception\WhoopsDisplayer.php:40 Stack trace: #0 [internal function]: Illuminate\Exception\Handler->handleShutdown() #1 {main} [] []
[2021-07-12 20:02:10] log.ERROR: Symfony\Component\Debug\Exception\FatalErrorException: Uncaught TypeError: Argument 1 passed to Illuminate\Exception\WhoopsDisplayer::display() must be an instance of Exception, instance of ParseError given, called in E:\xampp\htdocs\basic_auth_site\vendor\laravel\framework\src\Illuminate\Exception\Handler.php on line 275 and defined in E:\xampp\htdocs\basic_auth_site\vendor\laravel\framework\src\Illuminate\Exception\WhoopsDisplayer.php:40 Stack trace: #0 E:\xampp\htdocs\basic_auth_site\vendor\laravel\framework\src\Illuminate\Exception\Handler.php(275): Illuminate\Exception\WhoopsDisplayer->display(Object(ParseError)) #1 E:\xampp\htdocs\basic_auth_site\vendor\laravel\framework\src\Illuminate\Exception\Handler.php(162): Illuminate\Exception\Handler->displayException(Object(ParseError)) #2 [internal function]: Illuminate\Exception\Handler->handleException(Object(ParseError)) #3 {main}   thrown in E:\xampp\htdocs\basic_auth_site\vendor\laravel\framework\src\Illuminate\Exception\WhoopsDisplayer.php:40 Stack trace: #0 [internal function]: Illuminate\Exception\Handler->handleShutdown() #1 {main} [] []
[2021-07-12 20:02:32] log.ERROR: InvalidArgumentException: Routing requirement for "_method" must be a string. in E:\xampp\htdocs\basic_auth_site\vendor\symfony\routing\Symfony\Component\Routing\Route.php:582 Stack trace: #0 E:\xampp\htdocs\basic_auth_site\vendor\symfony\routing\Symfony\Component\Routing\Route.php(552): Symfony\Component\Routing\Route->sanitizeRequirement('_method', Array) #1 E:\xampp\htdocs\basic_auth_site\vendor\laravel\framework\src\Illuminate\Routing\Router.php(726): Symfony\Component\Routing\Route->setRequirement('_method', Array) #2 E:\xampp\htdocs\basic_auth_site\vendor\laravel\framework\src\Illuminate\Routing\Router.php(208): Illuminate\Routing\Router->createRoute(Array, '/', Array) #3 E:\xampp\htdocs\basic_auth_site\vendor\laravel\framework\src\Illuminate\Support\Facades\Facade.php(212): Illuminate\Routing\Router->match(Array, '/', Object(Closure)) #4 E:\xampp\htdocs\basic_auth_site\app\routes.php(17): Illuminate\Support\Facades\Facade::__callStatic('match', Array) #5 E:\xampp\htdocs\basic_auth_site\vendor\laravel\framework\src\Illuminate\Foundation\start.php(253): require('E:\\xampp\\htdocs...') #6 E:\xampp\htdocs\basic_auth_site\bootstrap\start.php(61): require('E:\\xampp\\htdocs...') #7 E:\xampp\htdocs\basic_auth_site\public\index.php(35): require_once('E:\\xampp\\htdocs...') #8 {main} [] []
[2021-07-12 20:02:34] log.ERROR: InvalidArgumentException: Routing requirement for "_method" must be a string. in E:\xampp\htdocs\basic_auth_site\vendor\symfony\routing\Symfony\Component\Routing\Route.php:582 Stack trace: #0 E:\xampp\htdocs\basic_auth_site\vendor\symfony\routing\Symfony\Component\Routing\Route.php(552): Symfony\Component\Routing\Route->sanitizeRequirement('_method', Array) #1 E:\xampp\htdocs\basic_auth_site\vendor\laravel\framework\src\Illuminate\Routing\Router.php(726): Symfony\Component\Routing\Route->setRequirement('_method', Array) #2 E:\xampp\htdocs\basic_auth_site\vendor\laravel\framework\src\Illuminate\Routing\Router.php(208): Illuminate\Routing\Router->createRoute(Array, '/', Array) #3 E:\xampp\htdocs\basic_auth_site\vendor\laravel\framework\src\Illuminate\Support\Facades\Facade.php(212): Illuminate\Routing\Router->match(Array, '/', Object(Closure)) #4 E:\xampp\htdocs\basic_auth_site\app\routes.php(17): Illuminate\Support\Facades\Facade::__callStatic('match', Array) #5 E:\xampp\htdocs\basic_auth_site\vendor\laravel\framework\src\Illuminate\Foundation\start.php(253): require('E:\\xampp\\htdocs...') #6 E:\xampp\htdocs\basic_auth_site\bootstrap\start.php(61): require('E:\\xampp\\htdocs...') #7 E:\xampp\htdocs\basic_auth_site\public\index.php(35): require_once('E:\\xampp\\htdocs...') #8 {main} [] []
[2021-07-12 20:02:35] log.ERROR: InvalidArgumentException: Routing requirement for "_method" must be a string. in E:\xampp\htdocs\basic_auth_site\vendor\symfony\routing\Symfony\Component\Routing\Route.php:582 Stack trace: #0 E:\xampp\htdocs\basic_auth_site\vendor\symfony\routing\Symfony\Component\Routing\Route.php(552): Symfony\Component\Routing\Route->sanitizeRequirement('_method', Array) #1 E:\xampp\htdocs\basic_auth_site\vendor\laravel\framework\src\Illuminate\Routing\Router.php(726): Symfony\Component\Routing\Route->setRequirement('_method', Array) #2 E:\xampp\htdocs\basic_auth_site\vendor\laravel\framework\src\Illuminate\Routing\Router.php(208): Illuminate\Routing\Router->createRoute(Array, '/', Array) #3 E:\xampp\htdocs\basic_auth_site\vendor\laravel\framework\src\Illuminate\Support\Facades\Facade.php(212): Illuminate\Routing\Router->match(Array, '/', Object(Closure)) #4 E:\xampp\htdocs\basic_auth_site\app\routes.php(17): Illuminate\Support\Facades\Facade::__callStatic('match', Array) #5 E:\xampp\htdocs\basic_auth_site\vendor\laravel\framework\src\Illuminate\Foundation\start.php(253): require('E:\\xampp\\htdocs...') #6 E:\xampp\htdocs\basic_auth_site\bootstrap\start.php(61): require('E:\\xampp\\htdocs...') #7 E:\xampp\htdocs\basic_auth_site\public\index.php(35): require_once('E:\\xampp\\htdocs...') #8 {main} [] []
[2021-07-12 20:05:20] log.ERROR: Symfony\Component\HttpKernel\Exception\MethodNotAllowedHttpException in E:\xampp\htdocs\basic_auth_site\vendor\laravel\framework\src\Illuminate\Routing\Router.php:1439 Stack trace: #0 E:\xampp\htdocs\basic_auth_site\vendor\laravel\framework\src\Illuminate\Routing\Router.php(1050): Illuminate\Routing\Router->handleRoutingException(Object(Symfony\Component\Routing\Exception\MethodNotAllowedException)) #1 E:\xampp\htdocs\basic_auth_site\vendor\laravel\framework\src\Illuminate\Routing\Router.php(1014): Illuminate\Routing\Router->findRoute(Object(Illuminate\Http\Request)) #2 E:\xampp\htdocs\basic_auth_site\vendor\laravel\framework\src\Illuminate\Foundation\Application.php(576): Illuminate\Routing\Router->dispatch(Object(Illuminate\Http\Request)) #3 E:\xampp\htdocs\basic_auth_site\vendor\laravel\framework\src\Illuminate\Foundation\Application.php(552): Illuminate\Foundation\Application->dispatch(Object(Illuminate\Http\Request)) #4 E:\xampp\htdocs\basic_auth_site\public\index.php(49): Illuminate\Foundation\Application->run() #5 {main} [] []
[2021-07-12 20:06:10] log.ERROR: Symfony\Component\HttpKernel\Exception\MethodNotAllowedHttpException in E:\xampp\htdocs\basic_auth_site\vendor\laravel\framework\src\Illuminate\Routing\Router.php:1439 Stack trace: #0 E:\xampp\htdocs\basic_auth_site\vendor\laravel\framework\src\Illuminate\Routing\Router.php(1050): Illuminate\Routing\Router->handleRoutingException(Object(Symfony\Component\Routing\Exception\MethodNotAllowedException)) #1 E:\xampp\htdocs\basic_auth_site\vendor\laravel\framework\src\Illuminate\Routing\Router.php(1014): Illuminate\Routing\Router->findRoute(Object(Illuminate\Http\Request)) #2 E:\xampp\htdocs\basic_auth_site\vendor\laravel\framework\src\Illuminate\Foundation\Application.php(576): Illuminate\Routing\Router->dispatch(Object(Illuminate\Http\Request)) #3 E:\xampp\htdocs\basic_auth_site\vendor\laravel\framework\src\Illuminate\Foundation\Application.php(552): Illuminate\Foundation\Application->dispatch(Object(Illuminate\Http\Request)) #4 E:\xampp\htdocs\basic_auth_site\public\index.php(49): Illuminate\Foundation\Application->run() #5 {main} [] []
[2021-07-12 20:06:13] log.ERROR: Symfony\Component\HttpKernel\Exception\MethodNotAllowedHttpException in E:\xampp\htdocs\basic_auth_site\vendor\laravel\framework\src\Illuminate\Routing\Router.php:1439 Stack trace: #0 E:\xampp\htdocs\basic_auth_site\vendor\laravel\framework\src\Illuminate\Routing\Router.php(1050): Illuminate\Routing\Router->handleRoutingException(Object(Symfony\Component\Routing\Exception\MethodNotAllowedException)) #1 E:\xampp\htdocs\basic_auth_site\vendor\laravel\framework\src\Illuminate\Routing\Router.php(1014): Illuminate\Routing\Router->findRoute(Object(Illuminate\Http\Request)) #2 E:\xampp\htdocs\basic_auth_site\vendor\laravel\framework\src\Illuminate\Foundation\Application.php(576): Illuminate\Routing\Router->dispatch(Object(Illuminate\Http\Request)) #3 E:\xampp\htdocs\basic_auth_site\vendor\laravel\framework\src\Illuminate\Foundation\Application.php(552): Illuminate\Foundation\Application->dispatch(Object(Illuminate\Http\Request)) #4 E:\xampp\htdocs\basic_auth_site\public\index.php(49): Illuminate\Foundation\Application->run() #5 {main} [] []
[2021-07-12 20:07:01] log.ERROR: Symfony\Component\HttpKernel\Exception\MethodNotAllowedHttpException in E:\xampp\htdocs\basic_auth_site\vendor\laravel\framework\src\Illuminate\Routing\Router.php:1439 Stack trace: #0 E:\xampp\htdocs\basic_auth_site\vendor\laravel\framework\src\Illuminate\Routing\Router.php(1050): Illuminate\Routing\Router->handleRoutingException(Object(Symfony\Component\Routing\Exception\MethodNotAllowedException)) #1 E:\xampp\htdocs\basic_auth_site\vendor\laravel\framework\src\Illuminate\Routing\Router.php(1014): Illuminate\Routing\Router->findRoute(Object(Illuminate\Http\Request)) #2 E:\xampp\htdocs\basic_auth_site\vendor\laravel\framework\src\Illuminate\Foundation\Application.php(576): Illuminate\Routing\Router->dispatch(Object(Illuminate\Http\Request)) #3 E:\xampp\htdocs\basic_auth_site\vendor\laravel\framework\src\Illuminate\Foundation\Application.php(552): Illuminate\Foundation\Application->dispatch(Object(Illuminate\Http\Request)) #4 E:\xampp\htdocs\basic_auth_site\public\index.php(49): Illuminate\Foundation\Application->run() #5 {main} [] []
[2021-07-12 20:07:04] log.ERROR: Symfony\Component\HttpKernel\Exception\MethodNotAllowedHttpException in E:\xampp\htdocs\basic_auth_site\vendor\laravel\framework\src\Illuminate\Routing\Router.php:1439 Stack trace: #0 E:\xampp\htdocs\basic_auth_site\vendor\laravel\framework\src\Illuminate\Routing\Router.php(1050): Illuminate\Routing\Router->handleRoutingException(Object(Symfony\Component\Routing\Exception\MethodNotAllowedException)) #1 E:\xampp\htdocs\basic_auth_site\vendor\laravel\framework\src\Illuminate\Routing\Router.php(1014): Illuminate\Routing\Router->findRoute(Object(Illuminate\Http\Request)) #2 E:\xampp\htdocs\basic_auth_site\vendor\laravel\framework\src\Illuminate\Foundation\Application.php(576): Illuminate\Routing\Router->dispatch(Object(Illuminate\Http\Request)) #3 E:\xampp\htdocs\basic_auth_site\vendor\laravel\framework\src\Illuminate\Foundation\Application.php(552): Illuminate\Foundation\Application->dispatch(Object(Illuminate\Http\Request)) #4 E:\xampp\htdocs\basic_auth_site\public\index.php(49): Illuminate\Foundation\Application->run() #5 {main} [] []
[2021-07-12 20:07:40] log.ERROR: Symfony\Component\HttpKernel\Exception\MethodNotAllowedHttpException in E:\xampp\htdocs\basic_auth_site\vendor\laravel\framework\src\Illuminate\Routing\Router.php:1439 Stack trace: #0 E:\xampp\htdocs\basic_auth_site\vendor\laravel\framework\src\Illuminate\Routing\Router.php(1050): Illuminate\Routing\Router->handleRoutingException(Object(Symfony\Component\Routing\Exception\MethodNotAllowedException)) #1 E:\xampp\htdocs\basic_auth_site\vendor\laravel\framework\src\Illuminate\Routing\Router.php(1014): Illuminate\Routing\Router->findRoute(Object(Illuminate\Http\Request)) #2 E:\xampp\htdocs\basic_auth_site\vendor\laravel\framework\src\Illuminate\Foundation\Application.php(576): Illuminate\Routing\Router->dispatch(Object(Illuminate\Http\Request)) #3 E:\xampp\htdocs\basic_auth_site\vendor\laravel\framework\src\Illuminate\Foundation\Application.php(552): Illuminate\Foundation\Application->dispatch(Object(Illuminate\Http\Request)) #4 E:\xampp\htdocs\basic_auth_site\public\index.php(49): Illuminate\Foundation\Application->run() #5 {main} [] []
[2021-07-12 20:07:43] log.ERROR: Symfony\Component\HttpKernel\Exception\MethodNotAllowedHttpException in E:\xampp\htdocs\basic_auth_site\vendor\laravel\framework\src\Illuminate\Routing\Router.php:1439 Stack trace: #0 E:\xampp\htdocs\basic_auth_site\vendor\laravel\framework\src\Illuminate\Routing\Router.php(1050): Illuminate\Routing\Router->handleRoutingException(Object(Symfony\Component\Routing\Exception\MethodNotAllowedException)) #1 E:\xampp\htdocs\basic_auth_site\vendor\laravel\framework\src\Illuminate\Routing\Router.php(1014): Illuminate\Routing\Router->findRoute(Object(Illuminate\Http\Request)) #2 E:\xampp\htdocs\basic_auth_site\vendor\laravel\framework\src\Illuminate\Foundation\Application.php(576): Illuminate\Routing\Router->dispatch(Object(Illuminate\Http\Request)) #3 E:\xampp\htdocs\basic_auth_site\vendor\laravel\framework\src\Illuminate\Foundation\Application.php(552): Illuminate\Foundation\Application->dispatch(Object(Illuminate\Http\Request)) #4 E:\xampp\htdocs\basic_auth_site\public\index.php(49): Illuminate\Foundation\Application->run() #5 {main} [] []
[2021-07-12 20:08:40] log.ERROR: Symfony\Component\HttpKernel\Exception\MethodNotAllowedHttpException in E:\xampp\htdocs\basic_auth_site\vendor\laravel\framework\src\Illuminate\Routing\Router.php:1439 Stack trace: #0 E:\xampp\htdocs\basic_auth_site\vendor\laravel\framework\src\Illuminate\Routing\Router.php(1050): Illuminate\Routing\Router->handleRoutingException(Object(Symfony\Component\Routing\Exception\MethodNotAllowedException)) #1 E:\xampp\htdocs\basic_auth_site\vendor\laravel\framework\src\Illuminate\Routing\Router.php(1014): Illuminate\Routing\Router->findRoute(Object(Illuminate\Http\Request)) #2 E:\xampp\htdocs\basic_auth_site\vendor\laravel\framework\src\Illuminate\Foundation\Application.php(576): Illuminate\Routing\Router->dispatch(Object(Illuminate\Http\Request)) #3 E:\xampp\htdocs\basic_auth_site\vendor\laravel\framework\src\Illuminate\Foundation\Application.php(552): Illuminate\Foundation\Application->dispatch(Object(Illuminate\Http\Request)) #4 E:\xampp\htdocs\basic_auth_site\public\index.php(49): Illuminate\Foundation\Application->run() #5 {main} [] []
[2021-07-12 20:09:06] log.ERROR: Symfony\Component\HttpKernel\Exception\MethodNotAllowedHttpException in E:\xampp\htdocs\basic_auth_site\vendor\laravel\framework\src\Illuminate\Routing\Router.php:1439 Stack trace: #0 E:\xampp\htdocs\basic_auth_site\vendor\laravel\framework\src\Illuminate\Routing\Router.php(1050): Illuminate\Routing\Router->handleRoutingException(Object(Symfony\Component\Routing\Exception\MethodNotAllowedException)) #1 E:\xampp\htdocs\basic_auth_site\vendor\laravel\framework\src\Illuminate\Routing\Router.php(1014): Illuminate\Routing\Router->findRoute(Object(Illuminate\Http\Request)) #2 E:\xampp\htdocs\basic_auth_site\vendor\laravel\framework\src\Illuminate\Foundation\Application.php(576): Illuminate\Routing\Router->dispatch(Object(Illuminate\Http\Request)) #3 E:\xampp\htdocs\basic_auth_site\vendor\laravel\framework\src\Illuminate\Foundation\Application.php(552): Illuminate\Foundation\Application->dispatch(Object(Illuminate\Http\Request)) #4 E:\xampp\htdocs\basic_auth_site\public\index.php(49): Illuminate\Foundation\Application->run() #5 {main} [] []
[2021-07-12 20:09:22] log.ERROR: Symfony\Component\HttpKernel\Exception\MethodNotAllowedHttpException in E:\xampp\htdocs\basic_auth_site\vendor\laravel\framework\src\Illuminate\Routing\Router.php:1439 Stack trace: #0 E:\xampp\htdocs\basic_auth_site\vendor\laravel\framework\src\Illuminate\Routing\Router.php(1050): Illuminate\Routing\Router->handleRoutingException(Object(Symfony\Component\Routing\Exception\MethodNotAllowedException)) #1 E:\xampp\htdocs\basic_auth_site\vendor\laravel\framework\src\Illuminate\Routing\Router.php(1014): Illuminate\Routing\Router->findRoute(Object(Illuminate\Http\Request)) #2 E:\xampp\htdocs\basic_auth_site\vendor\laravel\framework\src\Illuminate\Foundation\Application.php(576): Illuminate\Routing\Router->dispatch(Object(Illuminate\Http\Request)) #3 E:\xampp\htdocs\basic_auth_site\vendor\laravel\framework\src\Illuminate\Foundation\Application.php(552): Illuminate\Foundation\Application->dispatch(Object(Illuminate\Http\Request)) #4 E:\xampp\htdocs\basic_auth_site\public\index.php(49): Illuminate\Foundation\Application->run() #5 {main} [] []
[2021-07-12 20:09:49] log.ERROR: Symfony\Component\HttpKernel\Exception\MethodNotAllowedHttpException in E:\xampp\htdocs\basic_auth_site\vendor\laravel\framework\src\Illuminate\Routing\Router.php:1439 Stack trace: #0 E:\xampp\htdocs\basic_auth_site\vendor\laravel\framework\src\Illuminate\Routing\Router.php(1050): Illuminate\Routing\Router->handleRoutingException(Object(Symfony\Component\Routing\Exception\MethodNotAllowedException)) #1 E:\xampp\htdocs\basic_auth_site\vendor\laravel\framework\src\Illuminate\Routing\Router.php(1014): Illuminate\Routing\Router->findRoute(Object(Illuminate\Http\Request)) #2 E:\xampp\htdocs\basic_auth_site\vendor\laravel\framework\src\Illuminate\Foundation\Application.php(576): Illuminate\Routing\Router->dispatch(Object(Illuminate\Http\Request)) #3 E:\xampp\htdocs\basic_auth_site\vendor\laravel\framework\src\Illuminate\Foundation\Application.php(552): Illuminate\Foundation\Application->dispatch(Object(Illuminate\Http\Request)) #4 E:\xampp\htdocs\basic_auth_site\public\index.php(49): Illuminate\Foundation\Application->run() #5 {main} [] []
[2021-07-12 20:10:20] log.ERROR: Symfony\Component\HttpKernel\Exception\MethodNotAllowedHttpException in E:\xampp\htdocs\basic_auth_site\vendor\laravel\framework\src\Illuminate\Routing\Router.php:1439 Stack trace: #0 E:\xampp\htdocs\basic_auth_site\vendor\laravel\framework\src\Illuminate\Routing\Router.php(1050): Illuminate\Routing\Router->handleRoutingException(Object(Symfony\Component\Routing\Exception\MethodNotAllowedException)) #1 E:\xampp\htdocs\basic_auth_site\vendor\laravel\framework\src\Illuminate\Routing\Router.php(1014): Illuminate\Routing\Router->findRoute(Object(Illuminate\Http\Request)) #2 E:\xampp\htdocs\basic_auth_site\vendor\laravel\framework\src\Illuminate\Foundation\Application.php(576): Illuminate\Routing\Router->dispatch(Object(Illuminate\Http\Request)) #3 E:\xampp\htdocs\basic_auth_site\vendor\laravel\framework\src\Illuminate\Foundation\Application.php(552): Illuminate\Foundation\Application->dispatch(Object(Illuminate\Http\Request)) #4 E:\xampp\htdocs\basic_auth_site\public\index.php(49): Illuminate\Foundation\Application->run() #5 {main} [] []
[2021-07-12 20:19:01] log.ERROR: Symfony\Component\HttpKernel\Exception\NotFoundHttpException in E:\xampp\htdocs\basic_auth_site\vendor\laravel\framework\src\Illuminate\Routing\Router.php:1429 Stack trace: #0 E:\xampp\htdocs\basic_auth_site\vendor\laravel\framework\src\Illuminate\Routing\Router.php(1050): Illuminate\Routing\Router->handleRoutingException(Object(Symfony\Component\Routing\Exception\ResourceNotFoundException)) #1 E:\xampp\htdocs\basic_auth_site\vendor\laravel\framework\src\Illuminate\Routing\Router.php(1014): Illuminate\Routing\Router->findRoute(Object(Illuminate\Http\Request)) #2 E:\xampp\htdocs\basic_auth_site\vendor\laravel\framework\src\Illuminate\Foundation\Application.php(576): Illuminate\Routing\Router->dispatch(Object(Illuminate\Http\Request)) #3 E:\xampp\htdocs\basic_auth_site\vendor\laravel\framework\src\Illuminate\Foundation\Application.php(552): Illuminate\Foundation\Application->dispatch(Object(Illuminate\Http\Request)) #4 E:\xampp\htdocs\basic_auth_site\public\index.php(49): Illuminate\Foundation\Application->run() #5 {main} [] []
[2021-07-12 20:19:12] log.ERROR: Symfony\Component\HttpKernel\Exception\NotFoundHttpException in E:\xampp\htdocs\basic_auth_site\vendor\laravel\framework\src\Illuminate\Routing\Router.php:1429 Stack trace: #0 E:\xampp\htdocs\basic_auth_site\vendor\laravel\framework\src\Illuminate\Routing\Router.php(1050): Illuminate\Routing\Router->handleRoutingException(Object(Symfony\Component\Routing\Exception\ResourceNotFoundException)) #1 E:\xampp\htdocs\basic_auth_site\vendor\laravel\framework\src\Illuminate\Routing\Router.php(1014): Illuminate\Routing\Router->findRoute(Object(Illuminate\Http\Request)) #2 E:\xampp\htdocs\basic_auth_site\vendor\laravel\framework\src\Illuminate\Foundation\Application.php(576): Illuminate\Routing\Router->dispatch(Object(Illuminate\Http\Request)) #3 E:\xampp\htdocs\basic_auth_site\vendor\laravel\framework\src\Illuminate\Foundation\Application.php(552): Illuminate\Foundation\Application->dispatch(Object(Illuminate\Http\Request)) #4 E:\xampp\htdocs\basic_auth_site\public\index.php(49): Illuminate\Foundation\Application->run() #5 {main} [] []
[2021-07-12 20:22:51] log.ERROR: Symfony\Component\Debug\Exception\FatalErrorException: Uncaught TypeError: Argument 1 passed to Illuminate\Exception\WhoopsDisplayer::display() must be an instance of Exception, instance of ParseError given, called in E:\xampp\htdocs\basic_auth_site\vendor\laravel\framework\src\Illuminate\Exception\Handler.php on line 275 and defined in E:\xampp\htdocs\basic_auth_site\vendor\laravel\framework\src\Illuminate\Exception\WhoopsDisplayer.php:40 Stack trace: #0 E:\xampp\htdocs\basic_auth_site\vendor\laravel\framework\src\Illuminate\Exception\Handler.php(275): Illuminate\Exception\WhoopsDisplayer->display(Object(ParseError)) #1 E:\xampp\htdocs\basic_auth_site\vendor\laravel\framework\src\Illuminate\Exception\Handler.php(162): Illuminate\Exception\Handler->displayException(Object(ParseError)) #2 [internal function]: Illuminate\Exception\Handler->handleException(Object(ParseError)) #3 {main}   thrown in E:\xampp\htdocs\basic_auth_site\vendor\laravel\framework\src\Illuminate\Exception\WhoopsDisplayer.php:40 Stack trace: #0 [internal function]: Illuminate\Exception\Handler->handleShutdown() #1 {main} [] []
[2021-07-12 20:23:35] log.ERROR: ErrorException: Undefined variable: request in E:\xampp\htdocs\basic_auth_site\app\controllers\HomeController.php:80 Stack trace: #0 E:\xampp\htdocs\basic_auth_site\app\controllers\HomeController.php(80): Illuminate\Exception\Handler->handleError(8, 'Undefined varia...', 'E:\\xampp\\htdocs...', 80, Array) #1 [internal function]: HomeController->doLogin() #2 E:\xampp\htdocs\basic_auth_site\vendor\laravel\framework\src\Illuminate\Routing\Controllers\Controller.php(138): call_user_func_array(Array, Array) #3 E:\xampp\htdocs\basic_auth_site\vendor\laravel\framework\src\Illuminate\Routing\Controllers\Controller.php(115): Illuminate\Routing\Controllers\Controller->callMethod('doLogin', Array) #4 E:\xampp\htdocs\basic_auth_site\vendor\laravel\framework\src\Illuminate\Routing\Router.php(985): Illuminate\Routing\Controllers\Controller->callAction(Object(Illuminate\Foundation\Application), Object(Illuminate\Routing\Router), 'doLogin', Array) #5 [internal function]: Illuminate\Routing\Router->Illuminate\Routing\{closure}() #6 E:\xampp\htdocs\basic_auth_site\vendor\laravel\framework\src\Illuminate\Routing\Route.php(80): call_user_func_array(Object(Closure), Array) #7 E:\xampp\htdocs\basic_auth_site\vendor\laravel\framework\src\Illuminate\Routing\Route.php(47): Illuminate\Routing\Route->callCallable() #8 E:\xampp\htdocs\basic_auth_site\vendor\laravel\framework\src\Illuminate\Routing\Router.php(1016): Illuminate\Routing\Route->run(Object(Illuminate\Http\Request)) #9 E:\xampp\htdocs\basic_auth_site\vendor\laravel\framework\src\Illuminate\Foundation\Application.php(576): Illuminate\Routing\Router->dispatch(Object(Illuminate\Http\Request)) #10 E:\xampp\htdocs\basic_auth_site\vendor\laravel\framework\src\Illuminate\Foundation\Application.php(552): Illuminate\Foundation\Application->dispatch(Object(Illuminate\Http\Request)) #11 E:\xampp\htdocs\basic_auth_site\public\index.php(49): Illuminate\Foundation\Application->run() #12 {main} [] []
[2021-07-12 20:23:49] log.ERROR: ErrorException: Undefined variable: request in E:\xampp\htdocs\basic_auth_site\app\controllers\HomeController.php:80 Stack trace: #0 E:\xampp\htdocs\basic_auth_site\app\controllers\HomeController.php(80): Illuminate\Exception\Handler->handleError(8, 'Undefined varia...', 'E:\\xampp\\htdocs...', 80, Array) #1 [internal function]: HomeController->doLogin() #2 E:\xampp\htdocs\basic_auth_site\vendor\laravel\framework\src\Illuminate\Routing\Controllers\Controller.php(138): call_user_func_array(Array, Array) #3 E:\xampp\htdocs\basic_auth_site\vendor\laravel\framework\src\Illuminate\Routing\Controllers\Controller.php(115): Illuminate\Routing\Controllers\Controller->callMethod('doLogin', Array) #4 E:\xampp\htdocs\basic_auth_site\vendor\laravel\framework\src\Illuminate\Routing\Router.php(985): Illuminate\Routing\Controllers\Controller->callAction(Object(Illuminate\Foundation\Application), Object(Illuminate\Routing\Router), 'doLogin', Array) #5 [internal function]: Illuminate\Routing\Router->Illuminate\Routing\{closure}() #6 E:\xampp\htdocs\basic_auth_site\vendor\laravel\framework\src\Illuminate\Routing\Route.php(80): call_user_func_array(Object(Closure), Array) #7 E:\xampp\htdocs\basic_auth_site\vendor\laravel\framework\src\Illuminate\Routing\Route.php(47): Illuminate\Routing\Route->callCallable() #8 E:\xampp\htdocs\basic_auth_site\vendor\laravel\framework\src\Illuminate\Routing\Router.php(1016): Illuminate\Routing\Route->run(Object(Illuminate\Http\Request)) #9 E:\xampp\htdocs\basic_auth_site\vendor\laravel\framework\src\Illuminate\Foundation\Application.php(576): Illuminate\Routing\Router->dispatch(Object(Illuminate\Http\Request)) #10 E:\xampp\htdocs\basic_auth_site\vendor\laravel\framework\src\Illuminate\Foundation\Application.php(552): Illuminate\Foundation\Application->dispatch(Object(Illuminate\Http\Request)) #11 E:\xampp\htdocs\basic_auth_site\public\index.php(49): Illuminate\Foundation\Application->run() #12 {main} [] []
[2021-07-12 20:24:14] log.ERROR: Symfony\Component\Debug\Exception\FatalErrorException: Uncaught TypeError: Argument 1 passed to Illuminate\Exception\WhoopsDisplayer::display() must be an instance of Exception, instance of Error given, called in E:\xampp\htdocs\basic_auth_site\vendor\laravel\framework\src\Illuminate\Exception\Handler.php on line 275 and defined in E:\xampp\htdocs\basic_auth_site\vendor\laravel\framework\src\Illuminate\Exception\WhoopsDisplayer.php:40 Stack trace: #0 E:\xampp\htdocs\basic_auth_site\vendor\laravel\framework\src\Illuminate\Exception\Handler.php(275): Illuminate\Exception\WhoopsDisplayer->display(Object(Error)) #1 E:\xampp\htdocs\basic_auth_site\vendor\laravel\framework\src\Illuminate\Exception\Handler.php(162): Illuminate\Exception\Handler->displayException(Object(Error)) #2 [internal function]: Illuminate\Exception\Handler->handleException(Object(Error)) #3 {main}   thrown in E:\xampp\htdocs\basic_auth_site\vendor\laravel\framework\src\Illuminate\Exception\WhoopsDisplayer.php:40 Stack trace: #0 [internal function]: Illuminate\Exception\Handler->handleShutdown() #1 {main} [] []
[2021-07-12 20:24:29] log.ERROR: ErrorException: Undefined variable: request in E:\xampp\htdocs\basic_auth_site\app\controllers\HomeController.php:82 Stack trace: #0 E:\xampp\htdocs\basic_auth_site\app\controllers\HomeController.php(82): Illuminate\Exception\Handler->handleError(8, 'Undefined varia...', 'E:\\xampp\\htdocs...', 82, Array) #1 [internal function]: HomeController->doLogin() #2 E:\xampp\htdocs\basic_auth_site\vendor\laravel\framework\src\Illuminate\Routing\Controllers\Controller.php(138): call_user_func_array(Array, Array) #3 E:\xampp\htdocs\basic_auth_site\vendor\laravel\framework\src\Illuminate\Routing\Controllers\Controller.php(115): Illuminate\Routing\Controllers\Controller->callMethod('doLogin', Array) #4 E:\xampp\htdocs\basic_auth_site\vendor\laravel\framework\src\Illuminate\Routing\Router.php(985): Illuminate\Routing\Controllers\Controller->callAction(Object(Illuminate\Foundation\Application), Object(Illuminate\Routing\Router), 'doLogin', Array) #5 [internal function]: Illuminate\Routing\Router->Illuminate\Routing\{closure}() #6 E:\xampp\htdocs\basic_auth_site\vendor\laravel\framework\src\Illuminate\Routing\Route.php(80): call_user_func_array(Object(Closure), Array) #7 E:\xampp\htdocs\basic_auth_site\vendor\laravel\framework\src\Illuminate\Routing\Route.php(47): Illuminate\Routing\Route->callCallable() #8 E:\xampp\htdocs\basic_auth_site\vendor\laravel\framework\src\Illuminate\Routing\Router.php(1016): Illuminate\Routing\Route->run(Object(Illuminate\Http\Request)) #9 E:\xampp\htdocs\basic_auth_site\vendor\laravel\framework\src\Illuminate\Foundation\Application.php(576): Illuminate\Routing\Router->dispatch(Object(Illuminate\Http\Request)) #10 E:\xampp\htdocs\basic_auth_site\vendor\laravel\framework\src\Illuminate\Foundation\Application.php(552): Illuminate\Foundation\Application->dispatch(Object(Illuminate\Http\Request)) #11 E:\xampp\htdocs\basic_auth_site\public\index.php(49): Illuminate\Foundation\Application->run() #12 {main} [] []
[2021-07-12 20:25:04] log.ERROR: Symfony\Component\Debug\Exception\FatalErrorException: Uncaught TypeError: Argument 1 passed to Illuminate\Exception\WhoopsDisplayer::display() must be an instance of Exception, instance of ArgumentCountError given, called in E:\xampp\htdocs\basic_auth_site\vendor\laravel\framework\src\Illuminate\Exception\Handler.php on line 275 and defined in E:\xampp\htdocs\basic_auth_site\vendor\laravel\framework\src\Illuminate\Exception\WhoopsDisplayer.php:40 Stack trace: #0 E:\xampp\htdocs\basic_auth_site\vendor\laravel\framework\src\Illuminate\Exception\Handler.php(275): Illuminate\Exception\WhoopsDisplayer->display(Object(ArgumentCountError)) #1 E:\xampp\htdocs\basic_auth_site\vendor\laravel\framework\src\Illuminate\Exception\Handler.php(162): Illuminate\Exception\Handler->displayException(Object(ArgumentCountError)) #2 [internal function]: Illuminate\Exception\Handler->handleException(Object(ArgumentCountError)) #3 {main}   thrown in E:\xampp\htdocs\basic_auth_site\vendor\laravel\framework\src\Illuminate\Exception\WhoopsDisplayer.php:40 Stack trace: #0 [internal function]: Illuminate\Exception\Handler->handleShutdown() #1 {main} [] []
[2021-07-12 20:26:13] log.ERROR: Symfony\Component\Debug\Exception\FatalErrorException: Uncaught TypeError: Argument 1 passed to Illuminate\Exception\WhoopsDisplayer::display() must be an instance of Exception, instance of ArgumentCountError given, called in E:\xampp\htdocs\basic_auth_site\vendor\laravel\framework\src\Illuminate\Exception\Handler.php on line 275 and defined in E:\xampp\htdocs\basic_auth_site\vendor\laravel\framework\src\Illuminate\Exception\WhoopsDisplayer.php:40 Stack trace: #0 E:\xampp\htdocs\basic_auth_site\vendor\laravel\framework\src\Illuminate\Exception\Handler.php(275): Illuminate\Exception\WhoopsDisplayer->display(Object(ArgumentCountError)) #1 E:\xampp\htdocs\basic_auth_site\vendor\laravel\framework\src\Illuminate\Exception\Handler.php(162): Illuminate\Exception\Handler->displayException(Object(ArgumentCountError)) #2 [internal function]: Illuminate\Exception\Handler->handleException(Object(ArgumentCountError)) #3 {main}   thrown in E:\xampp\htdocs\basic_auth_site\vendor\laravel\framework\src\Illuminate\Exception\WhoopsDisplayer.php:40 Stack trace: #0 [internal function]: Illuminate\Exception\Handler->handleShutdown() #1 {main} [] []
[2021-07-12 20:29:29] log.ERROR: Symfony\Component\HttpKernel\Exception\NotFoundHttpException: Controller method not found. in E:\xampp\htdocs\basic_auth_site\vendor\laravel\framework\src\Illuminate\Routing\Controllers\Controller.php:290 Stack trace: #0 E:\xampp\htdocs\basic_auth_site\vendor\laravel\framework\src\Illuminate\Routing\Controllers\Controller.php(302): Illuminate\Routing\Controllers\Controller->missingMethod(Array) #1 [internal function]: Illuminate\Routing\Controllers\Controller->__call('doLogin(Request...', Array) #2 E:\xampp\htdocs\basic_auth_site\vendor\laravel\framework\src\Illuminate\Routing\Controllers\Controller.php(138): call_user_func_array(Array, Array) #3 E:\xampp\htdocs\basic_auth_site\vendor\laravel\framework\src\Illuminate\Routing\Controllers\Controller.php(115): Illuminate\Routing\Controllers\Controller->callMethod('doLogin(Request...', Array) #4 E:\xampp\htdocs\basic_auth_site\vendor\laravel\framework\src\Illuminate\Routing\Router.php(985): Illuminate\Routing\Controllers\Controller->callAction(Object(Illuminate\Foundation\Application), Object(Illuminate\Routing\Router), 'doLogin(Request...', Array) #5 [internal function]: Illuminate\Routing\Router->Illuminate\Routing\{closure}() #6 E:\xampp\htdocs\basic_auth_site\vendor\laravel\framework\src\Illuminate\Routing\Route.php(80): call_user_func_array(Object(Closure), Array) #7 E:\xampp\htdocs\basic_auth_site\vendor\laravel\framework\src\Illuminate\Routing\Route.php(47): Illuminate\Routing\Route->callCallable() #8 E:\xampp\htdocs\basic_auth_site\vendor\laravel\framework\src\Illuminate\Routing\Router.php(1016): Illuminate\Routing\Route->run(Object(Illuminate\Http\Request)) #9 E:\xampp\htdocs\basic_auth_site\vendor\laravel\framework\src\Illuminate\Foundation\Application.php(576): Illuminate\Routing\Router->dispatch(Object(Illuminate\Http\Request)) #10 E:\xampp\htdocs\basic_auth_site\vendor\laravel\framework\src\Illuminate\Foundation\Application.php(552): Illuminate\Foundation\Application->dispatch(Object(Illuminate\Http\Request)) #11 E:\xampp\htdocs\basic_auth_site\public\index.php(49): Illuminate\Foundation\Application->run() #12 {main} [] []
[2021-07-12 20:29:42] log.ERROR: Symfony\Component\HttpKernel\Exception\NotFoundHttpException: Controller method not found. in E:\xampp\htdocs\basic_auth_site\vendor\laravel\framework\src\Illuminate\Routing\Controllers\Controller.php:290 Stack trace: #0 E:\xampp\htdocs\basic_auth_site\vendor\laravel\framework\src\Illuminate\Routing\Controllers\Controller.php(302): Illuminate\Routing\Controllers\Controller->missingMethod(Array) #1 [internal function]: Illuminate\Routing\Controllers\Controller->__call('doLogin(Request...', Array) #2 E:\xampp\htdocs\basic_auth_site\vendor\laravel\framework\src\Illuminate\Routing\Controllers\Controller.php(138): call_user_func_array(Array, Array) #3 E:\xampp\htdocs\basic_auth_site\vendor\laravel\framework\src\Illuminate\Routing\Controllers\Controller.php(115): Illuminate\Routing\Controllers\Controller->callMethod('doLogin(Request...', Array) #4 E:\xampp\htdocs\basic_auth_site\vendor\laravel\framework\src\Illuminate\Routing\Router.php(985): Illuminate\Routing\Controllers\Controller->callAction(Object(Illuminate\Foundation\Application), Object(Illuminate\Routing\Router), 'doLogin(Request...', Array) #5 [internal function]: Illuminate\Routing\Router->Illuminate\Routing\{closure}() #6 E:\xampp\htdocs\basic_auth_site\vendor\laravel\framework\src\Illuminate\Routing\Route.php(80): call_user_func_array(Object(Closure), Array) #7 E:\xampp\htdocs\basic_auth_site\vendor\laravel\framework\src\Illuminate\Routing\Route.php(47): Illuminate\Routing\Route->callCallable() #8 E:\xampp\htdocs\basic_auth_site\vendor\laravel\framework\src\Illuminate\Routing\Router.php(1016): Illuminate\Routing\Route->run(Object(Illuminate\Http\Request)) #9 E:\xampp\htdocs\basic_auth_site\vendor\laravel\framework\src\Illuminate\Foundation\Application.php(576): Illuminate\Routing\Router->dispatch(Object(Illuminate\Http\Request)) #10 E:\xampp\htdocs\basic_auth_site\vendor\laravel\framework\src\Illuminate\Foundation\Application.php(552): Illuminate\Foundation\Application->dispatch(Object(Illuminate\Http\Request)) #11 E:\xampp\htdocs\basic_auth_site\public\index.php(49): Illuminate\Foundation\Application->run() #12 {main} [] []
[2021-07-12 20:29:48] log.ERROR: Symfony\Component\HttpKernel\Exception\NotFoundHttpException: Controller method not found. in E:\xampp\htdocs\basic_auth_site\vendor\laravel\framework\src\Illuminate\Routing\Controllers\Controller.php:290 Stack trace: #0 E:\xampp\htdocs\basic_auth_site\vendor\laravel\framework\src\Illuminate\Routing\Controllers\Controller.php(302): Illuminate\Routing\Controllers\Controller->missingMethod(Array) #1 [internal function]: Illuminate\Routing\Controllers\Controller->__call('doLogin()', Array) #2 E:\xampp\htdocs\basic_auth_site\vendor\laravel\framework\src\Illuminate\Routing\Controllers\Controller.php(138): call_user_func_array(Array, Array) #3 E:\xampp\htdocs\basic_auth_site\vendor\laravel\framework\src\Illuminate\Routing\Controllers\Controller.php(115): Illuminate\Routing\Controllers\Controller->callMethod('doLogin()', Array) #4 E:\xampp\htdocs\basic_auth_site\vendor\laravel\framework\src\Illuminate\Routing\Router.php(985): Illuminate\Routing\Controllers\Controller->callAction(Object(Illuminate\Foundation\Application), Object(Illuminate\Routing\Router), 'doLogin()', Array) #5 [internal function]: Illuminate\Routing\Router->Illuminate\Routing\{closure}() #6 E:\xampp\htdocs\basic_auth_site\vendor\laravel\framework\src\Illuminate\Routing\Route.php(80): call_user_func_array(Object(Closure), Array) #7 E:\xampp\htdocs\basic_auth_site\vendor\laravel\framework\src\Illuminate\Routing\Route.php(47): Illuminate\Routing\Route->callCallable() #8 E:\xampp\htdocs\basic_auth_site\vendor\laravel\framework\src\Illuminate\Routing\Router.php(1016): Illuminate\Routing\Route->run(Object(Illuminate\Http\Request)) #9 E:\xampp\htdocs\basic_auth_site\vendor\laravel\framework\src\Illuminate\Foundation\Application.php(576): Illuminate\Routing\Router->dispatch(Object(Illuminate\Http\Request)) #10 E:\xampp\htdocs\basic_auth_site\vendor\laravel\framework\src\Illuminate\Foundation\Application.php(552): Illuminate\Foundation\Application->dispatch(Object(Illuminate\Http\Request)) #11 E:\xampp\htdocs\basic_auth_site\public\index.php(49): Illuminate\Foundation\Application->run() #12 {main} [] []
[2021-07-12 20:29:58] log.ERROR: Symfony\Component\Debug\Exception\FatalErrorException: Uncaught TypeError: Argument 1 passed to Illuminate\Exception\WhoopsDisplayer::display() must be an instance of Exception, instance of ArgumentCountError given, called in E:\xampp\htdocs\basic_auth_site\vendor\laravel\framework\src\Illuminate\Exception\Handler.php on line 275 and defined in E:\xampp\htdocs\basic_auth_site\vendor\laravel\framework\src\Illuminate\Exception\WhoopsDisplayer.php:40 Stack trace: #0 E:\xampp\htdocs\basic_auth_site\vendor\laravel\framework\src\Illuminate\Exception\Handler.php(275): Illuminate\Exception\WhoopsDisplayer->display(Object(ArgumentCountError)) #1 E:\xampp\htdocs\basic_auth_site\vendor\laravel\framework\src\Illuminate\Exception\Handler.php(162): Illuminate\Exception\Handler->displayException(Object(ArgumentCountError)) #2 [internal function]: Illuminate\Exception\Handler->handleException(Object(ArgumentCountError)) #3 {main}   thrown in E:\xampp\htdocs\basic_auth_site\vendor\laravel\framework\src\Illuminate\Exception\WhoopsDisplayer.php:40 Stack trace: #0 [internal function]: Illuminate\Exception\Handler->handleShutdown() #1 {main} [] []
[2021-07-12 20:30:14] log.ERROR: Symfony\Component\Debug\Exception\FatalErrorException: Uncaught TypeError: Argument 1 passed to Illuminate\Exception\WhoopsDisplayer::display() must be an instance of Exception, instance of ArgumentCountError given, called in E:\xampp\htdocs\basic_auth_site\vendor\laravel\framework\src\Illuminate\Exception\Handler.php on line 275 and defined in E:\xampp\htdocs\basic_auth_site\vendor\laravel\framework\src\Illuminate\Exception\WhoopsDisplayer.php:40 Stack trace: #0 E:\xampp\htdocs\basic_auth_site\vendor\laravel\framework\src\Illuminate\Exception\Handler.php(275): Illuminate\Exception\WhoopsDisplayer->display(Object(ArgumentCountError)) #1 E:\xampp\htdocs\basic_auth_site\vendor\laravel\framework\src\Illuminate\Exception\Handler.php(162): Illuminate\Exception\Handler->displayException(Object(ArgumentCountError)) #2 [internal function]: Illuminate\Exception\Handler->handleException(Object(ArgumentCountError)) #3 {main}   thrown in E:\xampp\htdocs\basic_auth_site\vendor\laravel\framework\src\Illuminate\Exception\WhoopsDisplayer.php:40 Stack trace: #0 [internal function]: Illuminate\Exception\Handler->handleShutdown() #1 {main} [] []
[2021-07-12 20:30:24] log.ERROR: Symfony\Component\Debug\Exception\FatalErrorException: Uncaught TypeError: Argument 1 passed to Illuminate\Exception\WhoopsDisplayer::display() must be an instance of Exception, instance of ArgumentCountError given, called in E:\xampp\htdocs\basic_auth_site\vendor\laravel\framework\src\Illuminate\Exception\Handler.php on line 275 and defined in E:\xampp\htdocs\basic_auth_site\vendor\laravel\framework\src\Illuminate\Exception\WhoopsDisplayer.php:40 Stack trace: #0 E:\xampp\htdocs\basic_auth_site\vendor\laravel\framework\src\Illuminate\Exception\Handler.php(275): Illuminate\Exception\WhoopsDisplayer->display(Object(ArgumentCountError)) #1 E:\xampp\htdocs\basic_auth_site\vendor\laravel\framework\src\Illuminate\Exception\Handler.php(162): Illuminate\Exception\Handler->displayException(Object(ArgumentCountError)) #2 [internal function]: Illuminate\Exception\Handler->handleException(Object(ArgumentCountError)) #3 {main}   thrown in E:\xampp\htdocs\basic_auth_site\vendor\laravel\framework\src\Illuminate\Exception\WhoopsDisplayer.php:40 Stack trace: #0 [internal function]: Illuminate\Exception\Handler->handleShutdown() #1 {main} [] []
[2021-07-12 20:30:39] log.ERROR: ErrorException: Undefined variable: request in E:\xampp\htdocs\basic_auth_site\app\controllers\HomeController.php:87 Stack trace: #0 E:\xampp\htdocs\basic_auth_site\app\controllers\HomeController.php(87): Illuminate\Exception\Handler->handleError(8, 'Undefined varia...', 'E:\\xampp\\htdocs...', 87, Array) #1 [internal function]: HomeController->doLogin() #2 E:\xampp\htdocs\basic_auth_site\vendor\laravel\framework\src\Illuminate\Routing\Controllers\Controller.php(138): call_user_func_array(Array, Array) #3 E:\xampp\htdocs\basic_auth_site\vendor\laravel\framework\src\Illuminate\Routing\Controllers\Controller.php(115): Illuminate\Routing\Controllers\Controller->callMethod('doLogin', Array) #4 E:\xampp\htdocs\basic_auth_site\vendor\laravel\framework\src\Illuminate\Routing\Router.php(985): Illuminate\Routing\Controllers\Controller->callAction(Object(Illuminate\Foundation\Application), Object(Illuminate\Routing\Router), 'doLogin', Array) #5 [internal function]: Illuminate\Routing\Router->Illuminate\Routing\{closure}() #6 E:\xampp\htdocs\basic_auth_site\vendor\laravel\framework\src\Illuminate\Routing\Route.php(80): call_user_func_array(Object(Closure), Array) #7 E:\xampp\htdocs\basic_auth_site\vendor\laravel\framework\src\Illuminate\Routing\Route.php(47): Illuminate\Routing\Route->callCallable() #8 E:\xampp\htdocs\basic_auth_site\vendor\laravel\framework\src\Illuminate\Routing\Router.php(1016): Illuminate\Routing\Route->run(Object(Illuminate\Http\Request)) #9 E:\xampp\htdocs\basic_auth_site\vendor\laravel\framework\src\Illuminate\Foundation\Application.php(576): Illuminate\Routing\Router->dispatch(Object(Illuminate\Http\Request)) #10 E:\xampp\htdocs\basic_auth_site\vendor\laravel\framework\src\Illuminate\Foundation\Application.php(552): Illuminate\Foundation\Application->dispatch(Object(Illuminate\Http\Request)) #11 E:\xampp\htdocs\basic_auth_site\public\index.php(49): Illuminate\Foundation\Application->run() #12 {main} [] []
[2021-07-12 20:30:44] log.ERROR: Symfony\Component\Debug\Exception\FatalErrorException: Uncaught TypeError: Argument 1 passed to Illuminate\Exception\WhoopsDisplayer::display() must be an instance of Exception, instance of ArgumentCountError given, called in E:\xampp\htdocs\basic_auth_site\vendor\laravel\framework\src\Illuminate\Exception\Handler.php on line 275 and defined in E:\xampp\htdocs\basic_auth_site\vendor\laravel\framework\src\Illuminate\Exception\WhoopsDisplayer.php:40 Stack trace: #0 E:\xampp\htdocs\basic_auth_site\vendor\laravel\framework\src\Illuminate\Exception\Handler.php(275): Illuminate\Exception\WhoopsDisplayer->display(Object(ArgumentCountError)) #1 E:\xampp\htdocs\basic_auth_site\vendor\laravel\framework\src\Illuminate\Exception\Handler.php(162): Illuminate\Exception\Handler->displayException(Object(ArgumentCountError)) #2 [internal function]: Illuminate\Exception\Handler->handleException(Object(ArgumentCountError)) #3 {main}   thrown in E:\xampp\htdocs\basic_auth_site\vendor\laravel\framework\src\Illuminate\Exception\WhoopsDisplayer.php:40 Stack trace: #0 [internal function]: Illuminate\Exception\Handler->handleShutdown() #1 {main} [] []
[2021-07-12 20:30:51] log.ERROR: Symfony\Component\Debug\Exception\FatalErrorException: Uncaught TypeError: Argument 1 passed to Illuminate\Exception\WhoopsDisplayer::display() must be an instance of Exception, instance of ParseError given, called in E:\xampp\htdocs\basic_auth_site\vendor\laravel\framework\src\Illuminate\Exception\Handler.php on line 275 and defined in E:\xampp\htdocs\basic_auth_site\vendor\laravel\framework\src\Illuminate\Exception\WhoopsDisplayer.php:40 Stack trace: #0 E:\xampp\htdocs\basic_auth_site\vendor\laravel\framework\src\Illuminate\Exception\Handler.php(275): Illuminate\Exception\WhoopsDisplayer->display(Object(ParseError)) #1 E:\xampp\htdocs\basic_auth_site\vendor\laravel\framework\src\Illuminate\Exception\Handler.php(162): Illuminate\Exception\Handler->displayException(Object(ParseError)) #2 [internal function]: Illuminate\Exception\Handler->handleException(Object(ParseError)) #3 {main}   thrown in E:\xampp\htdocs\basic_auth_site\vendor\laravel\framework\src\Illuminate\Exception\WhoopsDisplayer.php:40 Stack trace: #0 [internal function]: Illuminate\Exception\Handler->handleShutdown() #1 {main} [] []
[2021-07-12 20:30:52] log.ERROR: Symfony\Component\Debug\Exception\FatalErrorException: Uncaught TypeError: Argument 1 passed to Illuminate\Exception\WhoopsDisplayer::display() must be an instance of Exception, instance of ParseError given, called in E:\xampp\htdocs\basic_auth_site\vendor\laravel\framework\src\Illuminate\Exception\Handler.php on line 275 and defined in E:\xampp\htdocs\basic_auth_site\vendor\laravel\framework\src\Illuminate\Exception\WhoopsDisplayer.php:40 Stack trace: #0 E:\xampp\htdocs\basic_auth_site\vendor\laravel\framework\src\Illuminate\Exception\Handler.php(275): Illuminate\Exception\WhoopsDisplayer->display(Object(ParseError)) #1 E:\xampp\htdocs\basic_auth_site\vendor\laravel\framework\src\Illuminate\Exception\Handler.php(162): Illuminate\Exception\Handler->displayException(Object(ParseError)) #2 [internal function]: Illuminate\Exception\Handler->handleException(Object(ParseError)) #3 {main}   thrown in E:\xampp\htdocs\basic_auth_site\vendor\laravel\framework\src\Illuminate\Exception\WhoopsDisplayer.php:40 Stack trace: #0 [internal function]: Illuminate\Exception\Handler->handleShutdown() #1 {main} [] []
[2021-07-12 20:31:02] log.ERROR: ErrorException: Undefined variable: request in E:\xampp\htdocs\basic_auth_site\app\controllers\HomeController.php:87 Stack trace: #0 E:\xampp\htdocs\basic_auth_site\app\controllers\HomeController.php(87): Illuminate\Exception\Handler->handleError(8, 'Undefined varia...', 'E:\\xampp\\htdocs...', 87, Array) #1 [internal function]: HomeController->doLogin() #2 E:\xampp\htdocs\basic_auth_site\vendor\laravel\framework\src\Illuminate\Routing\Controllers\Controller.php(138): call_user_func_array(Array, Array) #3 E:\xampp\htdocs\basic_auth_site\vendor\laravel\framework\src\Illuminate\Routing\Controllers\Controller.php(115): Illuminate\Routing\Controllers\Controller->callMethod('doLogin', Array) #4 E:\xampp\htdocs\basic_auth_site\vendor\laravel\framework\src\Illuminate\Routing\Router.php(985): Illuminate\Routing\Controllers\Controller->callAction(Object(Illuminate\Foundation\Application), Object(Illuminate\Routing\Router), 'doLogin', Array) #5 [internal function]: Illuminate\Routing\Router->Illuminate\Routing\{closure}() #6 E:\xampp\htdocs\basic_auth_site\vendor\laravel\framework\src\Illuminate\Routing\Route.php(80): call_user_func_array(Object(Closure), Array) #7 E:\xampp\htdocs\basic_auth_site\vendor\laravel\framework\src\Illuminate\Routing\Route.php(47): Illuminate\Routing\Route->callCallable() #8 E:\xampp\htdocs\basic_auth_site\vendor\laravel\framework\src\Illuminate\Routing\Router.php(1016): Illuminate\Routing\Route->run(Object(Illuminate\Http\Request)) #9 E:\xampp\htdocs\basic_auth_site\vendor\laravel\framework\src\Illuminate\Foundation\Application.php(576): Illuminate\Routing\Router->dispatch(Object(Illuminate\Http\Request)) #10 E:\xampp\htdocs\basic_auth_site\vendor\laravel\framework\src\Illuminate\Foundation\Application.php(552): Illuminate\Foundation\Application->dispatch(Object(Illuminate\Http\Request)) #11 E:\xampp\htdocs\basic_auth_site\public\index.php(49): Illuminate\Foundation\Application->run() #12 {main} [] []
